Workbook
Name Z_689895ED_8DF8_466C_90EE_5C2362D49AE1__wvu_PrintArea: 'Folha de salarios'!$A$4:$AA$42
Name Z_689895ED_8DF8_466C_90EE_5C2362D49AE1__wvu_PrintArea: Sindicate!$A$1:$D$40

Sheet Folha de salarios
A4: FOLHA DE SALARIOS | AG4: PAGINA 1
H5: EMPRESA : | M5: LANDCO LIMITADA | U5: NUIT : | W5: 400122792 | AF5: ANO : | AG5: 2025
H6: ACTIVIDADE : | I6: ACTIVIDADE : | M6: TURISMO | U6: LOCALIDADE : | W6: VILANCULOS | AF6: MES : | AG6: JANEIRIO
A8: NO | C8: NOME DO TRABALHADOR | D8: Engagement Date | E8: Discharge Date | F8: NUIT NO | G8: CATEGORIA | H8: RETRIBUICAO | Z8: DESCONTOS
H9: Salario Base 2024 | I9: 1.09 | J9: ALIMENTACAO | K9: Pagamentos Retroativos (Back Payment) | L9: DIAS DE TRABALHO | M9: SALARIO MENSAL | N9: NIGHTSHIFT HOURS | O9: 25% GUARDAS | P9: HORAS CALCULADO 1.5 | Q9: VALOR PARA TRABALHOS EXTRAORDINARIOS (CALCULADOOS 1.5) | R9: HORAS CALCULADO 2 | S9: VALOR PARA TRABALHOS EXTRAORDINARIO (CALCULADO 2) | T9: PREMIOS | U9: GRATIFICACOES | V9: DIAS DE FERIAS | W9: FERIA MONTANTE | X9: Total de Remuneração Mensal | Y9: Salário adiantado (Advance) | Z9: IRPS (A) | AA9: DIVIDA (A) | AB9: INSS (A) | AC9: SIND (A) | AD9: TOTAL DEDUCTIONS | AE9: SALARIO LIQUIDO | AF9: ARREDONDAMENTO | AG9: RUBRICA
A10: 1 | B10: AM | C10: MARCO BEBE GIMO | G10: GERENTE | H10: 74180 | I10: =+H10*$I$9+143.8-8000 -> 73000 | J10: 8000 | K10: 0 | L10: 30 | M10: =I10/30*L10+J10+K10 -> 81000 | P10: 0 | Q10: =H10/192*P10*1.5 -> 0 | S10: =M10/192*R10*2 -> 0 | U10: 0 | V10: 0 | W10: =M10/30*V10 -> 0 | X10: =M10+O10+Q10+S10+T10+U10+W10 -> 81000 | Z10: 10437.5 | AB10: =X10*3% -> 2430 | AC10: =X10*0.01 -> 810 | AD10: =+Y10+Z10+AA10+AB10+AC10 -> 13677.5 | AE10: =X10-AD10 -> 67322.5 | AF10: 304762846 | AG10: =SUM(X10:X17) -> 174740 | AH10: =+AG10*1.04 -> 181729.6
A11: =+A10+1 -> 2 | B11: AM | C11: ARMINDO QUETANE HOU | G11: GUARDA | H11: 10400 | I11: =+H11*$I$9 -> 11336 | K11: 0 | L11: 30 | M11: =I11/30*L11+K11 -> 11336 | N11: 160 | O11: =+M11/L11/8*N11*0.25 -> 1889.3333 | P11: 0 | Q11: =H11/192*P11*1.5 -> 0 | R11: =4.5*8 -> 36 | S11: =M11/192*R11*2 -> 4251 | U11: 0 | V11: 0 | W11: =M11/30*V11 -> 0 | X11: =M11+O11+Q11+S11+T11+U11+W11 -> 17476.333 | AB11: =X11*3% -> 524.29 | AC11: =X11*0.01 -> 174.76333 | AD11: =+Y11+Z11+AA11+AB11+AC11 -> 699.05333 | AE11: =X11-AD11 -> 16777.28 | AF11: 312688813
A12: =+A11+1 -> 3 | B12: AM | C12: CONSTANTINO JOSE PENGA | G12: GUARDA | H12: 10400 | I12: =+H12*$I$9 -> 11336 | K12: 0 | L12: 30 | M12: =I12/30*L12+K12 -> 11336 | N12: 160 | O12: =+M12/L12/8*N12*0.25 -> 1889.3333 | P12: 0 | Q12: =H12/192*P12*1.5 -> 0 | R12: =5*8 -> 40 | S12: =M12/192*R12*2 -> 4723.3333 | U12: 0 | V12: 0 | W12: =M12/30*V12 -> 0 | X12: =M12+O12+Q12+S12+T12+U12+W12 -> 17948.667 | AB12: =X12*3% -> 538.46 | AC12: =X12*0.01 -> 179.48667 | AD12: =+Y12+Z12+AA12+AB12+AC12 -> 717.94667 | AE12: =X12-AD12 -> 17230.72 | AF12: 88904090
A13: =+A12+1 -> 4 | B13: AM | C13: ANSELMO LUCAS HUO | G13: GUARDA | H13: 10400 | I13: =+H13*$I$9 -> 11336 | K13: 0 | L13: 30 | M13: =I13/30*L13+K13 -> 11336 | N13: 160 | O13: =+M13/L13/8*N13*0.25 -> 1889.3333 | P13: 0 | Q13: =H13/192*P13*1.5 -> 0 | R13: 8 | S13: =M13/192*R13*2 -> 944.66667 | U13: 0 | V13: 0 | W13: =M13/30*V13 -> 0 | X13: =M13+O13+Q13+S13+T13+U13+W13 -> 14170 | AB13: =X13*3% -> 425.1 | AC13: =X13*0.01 -> 141.7 | AD13: =+Y13+Z13+AA13+AB13+AC13 -> 566.8 | AE13: =X13-AD13 -> 13603.2 | AF13: 311846368
A14: =+A13+1 -> 5 | B14: AM | C14: CISTORA JOAO TANGUNE | G14: EMPREGADA | H14: 10000 | I14: =+H14*$I$9 -> 10900 | K14: 0 | L14: 30 | M14: =I14/30*L14+K14 -> 10900 | O14: =+M14/L14/8*N14*0.25 -> 0 | P14: 0 | Q14: =H14/192*P14*1.5 -> 0 | S14: =M14/192*R14*2 -> 0 | U14: 0 | V14: 0 | W14: =M14/30*V14 -> 0 | X14: =M14+O14+Q14+S14+T14+U14+W14 -> 10900 | AB14: =X14*3% -> 327 | AC14: =X14*0.01 -> 109 | AD14: =+Y14+Z14+AA14+AB14+AC14 -> 436 | AE14: =X14-AD14 -> 10464 | AF14: 465121888
A15: =+A14+1 -> 6 | B15: AM | C15: EMILIO GELSON ZIBANE | G15: JARDINERO | H15: 10500 | I15: =+H15*$I$9 -> 11445 | K15: 0 | L15: 30 | M15: =I15/30*L15+K15 -> 11445 | O15: =+M15/L15/8*N15*0.25 -> 0 | P15: 0 | Q15: =H15/192*P15*1.5 -> 0 | S15: =M15/192*R15*2 -> 0 | U15: 0 | V15: 0 | W15: =M15/30*V15 -> 0 | X15: =M15+O15+Q15+S15+T15+U15+W15 -> 11445 | AB15: =X15*3% -> 343.35 | AC15: =X15*0.01 -> 114.45 | AD15: =+Y15+Z15+AA15+AB15+AC15 -> 457.8 | AE15: =X15-AD15 -> 10987.2 | AF15: 465126932
A16: =+A15+1 -> 7 | B16: AM | C16: ALMEIDA ANTONIO VILANCULO | F16: 151700586 | G16: JARDINERO | H16: 10000 | I16: =+H16*$I$9 -> 10900 | K16: 0 | L16: 30 | M16: =I16/30*L16+K16 -> 10900 | O16: =+M16/L16/8*N16*0.25 -> 0 | P16: 0 | Q16: =H16/192*P16*1.5 -> 0 | S16: =M16/192*R16*2 -> 0 | U16: 0 | V16: 0 | W16: =M16/30*V16 -> 0 | X16: =M16+O16+Q16+S16+T16+U16+W16 -> 10900 | AB16: =X16*3% -> 327 | AC16: =X16*0.01 -> 109 | AD16: =+Y16+Z16+AA16+AB16+AC16 -> 436 | AE16: =X16-AD16 -> 10464 | AF16: 784781120
A17: =+A16+1 -> 8 | B17: AM | C17: FELIX CARLOS MASSUANGANHE | G17: JARDINERO | H17: 10000 | I17: =+H17*$I$9 -> 10900 | K17: 0 | L17: 30 | M17: =I17/30*L17+K17 -> 10900 | O17: =+M17/L17/8*N17*0.25 -> 0 | P17: 0 | Q17: =H17/192*P17*1.5 -> 0 | S17: =M17/192*R17*2 -> 0 | U17: 0 | V17: 0 | W17: =M17/30*V17 -> 0 | X17: =M17+O17+Q17+S17+T17+U17+W17 -> 10900 | Y17: =2500+3000 -> 5500 | AB17: =X17*3% -> 327 | AC17: =X17*0.01 -> 109 | AD17: =+Y17+Z17+AA17+AB17+AC17 -> 5936 | AE17: =X17-AD17 -> 4964 | AF17: 1236577535
A18: =+A17+1 -> 9 | B18: H1 | C18: GILDA DALARIO FALACO MUABASA | G18: EMPREGADA | H18: 10050 | I18: =+H18*$I$9+0.5 -> 10955 | K18: 0 | L18: 30 | M18: =I18/30*L18+K18 -> 10955 | O18: =+M18/L18/8*N18*0.25 -> 0 | P18: 0 | Q18: =H18/192*P18*1.5 -> 0 | S18: =M18/192*R18*2 -> 0 | U18: 0 | V18: 0 | W18: =M18/30*V18 -> 0 | X18: =M18+O18+Q18+S18+T18+U18+W18 -> 10955 | AB18: =X18*3% -> 328.65 | AC18: =X18*0.01 -> 109.55 | AD18: =+Y18+Z18+AA18+AB18+AC18 -> 438.2 | AE18: =X18-AD18 -> 10516.8 | AF18: 312354163 | AG18: =SUM(X18:X20)-6500 -> 33449 | AH18: =+AG18*1.04 -> 34786.96
A19: =+A18+1 -> 10 | B19: H1 | C19: SERGIO FENIASSE BUANE | G19: COZINHEIRA | H19: 13600 | I19: =+H19*$I$9 -> 14824 | K19: 0 | L19: 30 | M19: =I19/30*L19+K19 -> 14824 | P19: 0 | Q19: =H19/192*P19*1.5 -> 0 | S19: =M19/192*R19*2 -> 0 | U19: 0 | V19: 0 | W19: =M19/30*V19 -> 0 | X19: =M19+O19+Q19+S19+T19+U19+W19 -> 14824 | AB19: =X19*3% -> 444.72 | AC19: =X19*0.01 -> 148.24 | AD19: =+Y19+Z19+AA19+AB19+AC19 -> 592.96 | AE19: =X19-AD19 -> 14231.04 | AF19: 426758485
A20: =+A19+1 -> 11 | B20: H1/H4 | C20: AMINOSSE ARNALDO TANGUNE | G20: CAPITÃO DE BARCO | H20: 13000 | I20: =+H20*$I$9 -> 14170 | K20: 0 | L20: 30 | M20: =I20/30*L20+K20 -> 14170 | P20: 0 | Q20: =H20/192*P20*1.5 -> 0 | S20: =M20/192*R20*2 -> 0 | U20: 0 | V20: 0 | W20: =M20/30*V20 -> 0 | X20: =M20+O20+Q20+S20+T20+U20+W20 -> 14170 | AB20: =X20*3% -> 425.1 | AC20: =X20*0.01 -> 141.7 | AD20: =+Y20+Z20+AA20+AB20+AC20 -> 566.8 | AE20: =X20-AD20 -> 13603.2 | AF20: 000800007745713610195
A21: =+A20+1 -> 12 | B21: H2 | C21: SERGIO FRANCISCO TANGUNE ZITO | G21: GHILLIE | H21: 13650 | I21: =+H21*$I$9+0.5 -> 14879 | K21: 0 | L21: 30 | M21: =I21/30*L21+K21 -> 14879 | P21: 0 | Q21: =H21/192*P21*1.5 -> 0 | S21: =M21/192*R21*2 -> 0 | U21: 0 | V21: 0 | W21: =M21/30*V21 -> 0 | X21: =M21+O21+Q21+S21+T21+U21+W21 -> 14879 | AB21: =X21*3% -> 446.37 | AC21: =X21*0.01 -> 148.79 | AD21: =+Y21+Z21+AA21+AB21+AC21 -> 595.16 | AE21: =X21-AD21 -> 14283.84 | AF21: 311712702 | AG21: =SUM(X21:X24) -> 58534 | AH21: =+AG21*1.04 -> 60875.36
A22: =+A21+1 -> 13 | B22: H2 | C22: VITORIA FRANCISCO ZIBANE | G22: EMPREGADA | H22: 10050 | I22: =+H22*$I$9+0.5 -> 10955 | K22: 0 | L22: 30 | M22: =I22/30*L22+K22 -> 10955 | P22: 0 | Q22: =H22/192*P22*1.5 -> 0 | S22: =M22/192*R22*2 -> 0 | U22: 0 | V22: 0 | W22: =M22/30*V22 -> 0 | X22: =M22+O22+Q22+S22+T22+U22+W22 -> 10955 | AB22: =X22*3% -> 328.65 | AC22: =X22*0.01 -> 109.55 | AD22: =+Y22+Z22+AA22+AB22+AC22 -> 438.2 | AE22: =X22-AD22 -> 10516.8 | AF22: 98059241
A23: =+A22+1 -> 14 | B23: H2 | C23: INACIO FABIAO TIMBE | G23: CAPITÃO DE BARCO | H23: 15000 | I23: =+H23*$I$9 -> 16350 | K23: 0 | L23: 30 | M23: =I23/30*L23+K23 -> 16350 | P23: 0 | Q23: =H23/192*P23*1.5 -> 0 | S23: =M23/192*R23*2 -> 0 | U23: 0 | V23: 0 | W23: =M23/30*V23 -> 0 | X23: =M23+O23+Q23+S23+T23+U23+W23 -> 16350 | AB23: =X23*3% -> 490.5 | AC23: =X23*0.01 -> 163.5 | AD23: =+Y23+Z23+AA23+AB23+AC23 -> 654 | AE23: =X23-AD23 -> 15696 | AF23: 411440730
A24: =+A23+1 -> 15 | B24: H2 | C24: CALDERONE AGOSTINHO CHIVALE | F24: 147597851 | G24: COZINHEIRA | H24: 15000 | I24: =+H24*$I$9 -> 16350 | K24: 0 | L24: 30 | M24: =I24/30*L24+K24 -> 16350 | P24: 0 | Q24: =H24/192*P24*1.5 -> 0 | S24: =M24/192*R24*2 -> 0 | U24: 0 | V24: 0 | W24: =M24/30*V24 -> 0 | X24: =M24+O24+Q24+S24+T24+U24+W24 -> 16350 | Y24: =+Q24+S24 -> 0 | AB24: =X24*3% -> 490.5 | AC24: =X24*0.01 -> 163.5 | AD24: =+Y24+Z24+AA24+AB24+AC24 -> 654 | AE24: =X24-AD24 -> 15696 | AF24: '000800004412814610113
A25: =+A24+1 -> 16 | B25: H3 | C25: PEDRO SEBASTIAO NHAMIRE | G25: JARDINERO/GHILLIE | H25: 10500 | I25: =+H25*$I$9 -> 11445 | K25: 0 | L25: 30 | M25: =I25/30*L25+K25 -> 11445 | P25: 0 | Q25: =H25/192*P25*1.5 -> 0 | S25: =M25/192*R25*2 -> 0 | U25: 0 | V25: 0 | W25: =M25/30*V25 -> 0 | X25: =M25+O25+Q25+S25+T25+U25+W25 -> 11445 | AB25: =X25*3% -> 343.35 | AC25: =X25*0.01 -> 114.45 | AD25: =+Y25+Z25+AA25+AB25+AC25 -> 457.8 | AE25: =X25-AD25 -> 10987.2 | AF25: 393221511 | AG25: =SUM(X25:X27) -> 36625 | AH25: =+AG25*1.04 -> 38090
A26: =+A25+1 -> 17 | B26: H3 | C26: ROCINA CAHIWANE TIMBE | G26: EMPREGADA | H26: 10050 | I26: =+H26*$I$9+0.5 -> 10955 | K26: 0 | L26: 30 | M26: =I26/30*L26+K26 -> 10955 | P26: 0 | Q26: =H26/192*P26*1.5 -> 0 | S26: =M26/192*R26*2 -> 0 | U26: 0 | V26: 0 | W26: =M26/30*V26 -> 0 | X26: =M26+O26+Q26+S26+T26+U26+W26 -> 10955 | AB26: =X26*3% -> 328.65 | AC26: =X26*0.01 -> 109.55 | AD26: =+Y26+Z26+AA26+AB26+AC26 -> 438.2 | AE26: =X26-AD26 -> 10516.8 | AF26: 313333863
A27: =+A26+1 -> 18 | B27: H3 | C27: ALEXANDRE LUCAS MASSUANGANHE | G27: COZINHEIRA | H27: 13050 | I27: =+H27*$I$9+0.5 -> 14225 | K27: 0 | L27: 30 | M27: =I27/30*L27+K27 -> 14225 | P27: 0 | Q27: =H27/192*P27*1.5 -> 0 | S27: =M27/192*R27*2 -> 0 | U27: 0 | V27: 0 | W27: =M27/30*V27 -> 0 | X27: =M27+O27+Q27+S27+T27+U27+W27 -> 14225 | AB27: =X27*3% -> 426.75 | AC27: =X27*0.01 -> 142.25 | AD27: =+Y27+Z27+AA27+AB27+AC27 -> 569 | AE27: =X27-AD27 -> 13656 | AF27: 305745068
A28: =+A27+1 -> 19 | B28: H4 | C28: JELSON QUALDADE ZIVANE | G28: JARDINERO/COZINHA | H28: 10500 | I28: =+H28*$I$9 -> 11445 | K28: 0 | L28: 30 | M28: =I28/30*L28+K28 -> 11445 | P28: 0 | Q28: =H28/192*P28*1.5 -> 0 | S28: =M28/192*R28*2 -> 0 | U28: 0 | V28: 0 | W28: =M28/30*V28 -> 0 | X28: =M28+O28+Q28+S28+T28+U28+W28 -> 11445 | Y28: 1500 | AB28: =X28*3% -> 343.35 | AC28: =X28*0.01 -> 114.45 | AD28: =+Y28+Z28+AA28+AB28+AC28 -> 1957.8 | AE28: =X28-AD28 -> 9487.2 | AF28: 311818141 | AG28: =SUM(X28:X30)+6500 -> 43125 | AH28: =+AG28*1.04 -> 44850
A29: =+A28+1 -> 20 | B29: H4 | C29: MONIS TSANZIUANE CHIVALE | G29: COZINHEIRA | H29: 13050 | I29: =+H29*$I$9+0.5 -> 14225 | K29: 0 | L29: 30 | M29: =I29/30*L29+K29 -> 14225 | P29: 0 | Q29: =H29/192*P29*1.5 -> 0 | S29: =M29/192*R29*2 -> 0 | U29: 0 | V29: 0 | W29: =M29/30*V29 -> 0 | X29: =M29+O29+Q29+S29+T29+U29+W29 -> 14225 | AB29: =X29*3% -> 426.75 | AC29: =X29*0.01 -> 142.25 | AD29: =+Y29+Z29+AA29+AB29+AC29 -> 569 | AE29: =X29-AD29 -> 13656 | AF29: 169475394
A30: =+A29+1 -> 21 | B30: H4 | C30: EVELIN NELSON BERNARDO | F30: 122598829 | G30: EMPREGADA | H30: 10050 | I30: =+H30*$I$9+0.5 -> 10955 | K30: 0 | L30: 30 | M30: =I30/30*L30+K30 -> 10955 | P30: 0 | Q30: =H30/192*P30*1.5 -> 0 | S30: =M30/192*R30*2 -> 0 | U30: 0 | V30: 0 | W30: =M30/30*V30 -> 0 | X30: =M30+O30+Q30+S30+T30+U30+W30 -> 10955 | AB30: =X30*3% -> 328.65 | AC30: =X30*0.01 -> 109.55 | AD30: =+Y30+Z30+AA30+AB30+AC30 -> 438.2 | AE30: =X30-AD30 -> 10516.8 | AF30: 257804370
K31: =SUM(K10:K30) -> 0 | M31: =SUM(M10:M30) -> 330886 | O31: =SUM(O10:O30) -> 5668 | P31: =SUM(P10:P30) -> 0 | Q31: =SUM(Q10:Q30) -> 0 | R31: =SUM(R10:R30) -> 84 | S31: =SUM(S10:S30) -> 9919 | T31: =SUM(T10:T30) -> 0 | U31: =SUM(U10:U30) -> 0 | V31: =SUM(V10:V30) -> 0 | ... AE31: =SUM(AE10:AE30) -> 315176.58 | AG31: =SUM(AG10:AG30) -> 346473
Z32: 7% INSS | AB32: =+X31*0.07 -> 24253.11 | AF32: 4% INSS | AG32: =+AG31*0.04 -> 13858.92
AE34: =SUM(AE31:AE33) -> 315176.58 | AG34: =SUM(AG31:AG32) -> 360331.92 | AH34: =SUM(AH10:AH33) -> 360331.92
Q36: DECLARACAO
A37: ( A ) | C37: Riscar o que nao interessa. | M37: Declaro que nesta data, efectuei o pagamento dos salarios constantes desta
A38: ( B ) | C38: Assinalar com M os trabalhadores de menor idade | M38: folha, aos trabalhadores nela mencionados, na presenca de duas testemunhas
A39: ( C ) | C39: Nao preencher quando se trata de trabalhadores ao dia. | M39: que comigo, pagador, vao assinar.
A40: ( D ) | C40: Descontos permitidos por lei
M41: Data :

Sheet Sindicate
A1: FOLHA DE SALARIOS | J1: PAGINA 1
C2: OCTOBRO 2025 | I2: ANO : | J2: 2024
I3: MES : | J3: SEPTEMBRO
A5: NO | C5: NOME DO TRABALHADOR | H5: IMPORTANCIA A PAGAR
D6: TOTAL | E6: SIND (A) | F6: TOTAL | G6: SALARIO LIQUIDO | J6: RUBRICA
A7: 1 | B7: AM | C7: MARCO BEBE GIMO | D7: =+'Folha de salarios'!X10 -> 81000 | E7: =D7*0.01 -> 810 | F7: =+#REF!+#REF!+#REF!+E7 -> #REF! | G7: =D7-F7 -> #REF! | H7: =MROUND(G7,5) -> #REF! | I7: 304762846 | J7: =SUM(D7:D13) -> 163840
A8: =+A7+1 -> 2 | B8: AM | C8: ARMINDO QUETANE HOU | D8: =+'Folha de salarios'!X11 -> 17476.333 | E8: =D8*0.01 -> 174.76333 | F8: =+#REF!+#REF!+#REF!+E8 -> #REF! | G8: =D8-F8 -> #REF! | H8: =MROUND(G8,5) -> #REF! | I8: 312688813
A9: =+A8+1 -> 3 | B9: AM | C9: CONSTANTINO JOSE PENGA | D9: =+'Folha de salarios'!X12 -> 17948.667 | E9: =D9*0.01 -> 179.48667 | F9: =+#REF!+#REF!+#REF!+E9 -> #REF! | G9: =D9-F9 -> #REF! | H9: =MROUND(G9,5) -> #REF! | I9: 88904090
A10: =+A9+1 -> 4 | B10: AM | C10: ANSELMO LUCAS HUO | D10: =+'Folha de salarios'!X13 -> 14170 | E10: =D10*0.01 -> 141.7 | F10: =+#REF!+#REF!+#REF!+E10 -> #REF! | G10: =D10-F10 -> #REF! | H10: =MROUND(G10,5) -> #REF! | I10: 311846368
A11: =+A10+1 -> 5 | B11: AM | C11: CISTORA JOAO TANGUNE | D11: =+'Folha de salarios'!X14 -> 10900 | E11: =D11*0.01 -> 109 | F11: =+#REF!+#REF!+#REF!+E11 -> #REF! | G11: =D11-F11 -> #REF! | H11: =MROUND(G11,5) -> #REF! | I11: 465121888
A12: =+A11+1 -> 6 | B12: AM | C12: EMELIO GELSON ZIBANE | D12: =+'Folha de salarios'!X15 -> 11445 | E12: =D12*0.01 -> 114.45 | F12: =+#REF!+#REF!+#REF!+E12 -> #REF! | G12: =D12-F12 -> #REF! | H12: =MROUND(G12,5) -> #REF! | I12: 465126932
A13: =+A12+1 -> 7 | B13: AM | C13: ALMEDIA ANTONIO VILANCULO | D13: =+'Folha de salarios'!X16 -> 10900 | E13: =D13*0.01 -> 109 | F13: =+#REF!+#REF!+#REF!+E13 -> #REF! | G13: =D13-F13 -> #REF! | H13: =MROUND(G13,5) -> #REF! | I13: 784781120
A14: =+A13+1 -> 8 | B14: AM | C14: FELIX CARLOS MASSUANGANHE | D14: =+'Folha de salarios'!X17 -> 10900 | E14: =D14*0.01 -> 109
A15: =+A14+1 -> 9 | B15: H1 | C15: GILDA DALARIO FALACO MUABASA | D15: =+'Folha de salarios'!X18 -> 10955 | E15: =D15*0.01 -> 109.55 | F15: =+#REF!+#REF!+#REF!+E15 -> #REF! | G15: =D15-F15 -> #REF! | H15: =MROUND(G15,5) -> #REF! | I15: 312354163 | J15: =SUM(D15:D17)-6500 -> 33449
A16: =+A15+1 -> 10 | B16: H1 | C16: SERGIO FENIASSE BUANE | D16: =+'Folha de salarios'!X19 -> 14824 | E16: =D16*0.01 -> 148.24 | F16: =+#REF!+#REF!+#REF!+E16 -> #REF! | G16: =D16-F16 -> #REF! | H16: =MROUND(G16,5) -> #REF! | I16: 426758485
A17: =+A16+1 -> 11 | B17: H1/H4 | C17: AMINOSSE ARNALDO TANGUNE | D17: =+'Folha de salarios'!X20 -> 14170 | E17: =D17*0.01 -> 141.7 | F17: =+#REF!+#REF!+#REF!+E17 -> #REF! | G17: =D17-F17 -> #REF! | H17: =MROUND(G17,5) -> #REF! | I17: 000800007745713610195
A18: =+A17+1 -> 12 | B18: H2 | C18: SERGIO FRANCISCO TANGUNE | D18: =+'Folha de salarios'!X21 -> 14879 | E18: =D18*0.01 -> 148.79 | F18: =+#REF!+#REF!+#REF!+E18 -> #REF! | G18: =D18-F18 -> #REF! | H18: =MROUND(G18,5) -> #REF! | I18: 311712702 | J18: =SUM(D18:D21) -> 58534
A19: =+A18+1 -> 13 | B19: H2 | C19: VITORIA FRANCISCO ZIBANE | D19: =+'Folha de salarios'!X22 -> 10955 | E19: =D19*0.01 -> 109.55 | F19: =+#REF!+#REF!+#REF!+E19 -> #REF! | G19: =D19-F19 -> #REF! | H19: =MROUND(G19,5) -> #REF! | I19: 98059241
A20: =+A19+1 -> 14 | B20: H2 | C20: INACIO FABIAO TIMBE | D20: =+'Folha de salarios'!X23 -> 16350 | E20: =D20*0.01 -> 163.5 | F20: =+#REF!+#REF!+#REF!+E20 -> #REF! | G20: =D20-F20 -> #REF! | H20: =MROUND(G20,5) -> #REF! | I20: 411440730
A21: =+A20+1 -> 15 | B21: H2 | C21: CALDERONE AGOSTINHO CHIVALE | D21: =+'Folha de salarios'!X24 -> 16350 | E21: =D21*0.01 -> 163.5 | F21: =+#REF!+#REF!+#REF!+E21 -> #REF! | G21: =D21-F21 -> #REF! | H21: =MROUND(G21,5) -> #REF! | I21: 000800004412814610113
A22: =+A21+1 -> 16 | B22: H3 | C22: ROCINA CAHIWANE TIMBE | D22: =+'Folha de salarios'!X25 -> 11445 | E22: =D22*0.01 -> 114.45 | F22: =+#REF!+#REF!+#REF!+E22 -> #REF! | G22: =D22-F22 -> #REF! | H22: =MROUND(G22,5) -> #REF! | I22: 313333863 | J22: =SUM(D22:D23) -> 22400
A23: =+A22+1 -> 17 | B23: H3 | C23: ALEXANDRE LUCAS MASSUANGANHE | D23: =+'Folha de salarios'!X26 -> 10955 | E23: =D23*0.01 -> 109.55 | F23: =+#REF!+#REF!+#REF!+E23 -> #REF! | G23: =D23-F23 -> #REF! | H23: =MROUND(G23,5) -> #REF! | I23: 305745068
A24: =+A23+1 -> 18 | B24: H3 | C24: PEDRO SEBASTIAO NHAMIRE | D24: =+'Folha de salarios'!X27 -> 14225 | E24: =D24*0.01 -> 142.25 | F24: =+#REF!+#REF!+#REF!+E24 -> #REF! | G24: =D24-F24 -> #REF! | H24: =MROUND(G24,5) -> #REF! | I24: 393221511
A25: =+A24+1 -> 19 | B25: H4 | C25: JELSON QUALDADE ZIVANE | D25: =+'Folha de salarios'!X28 -> 11445 | E25: =D25*0.01 -> 114.45 | F25: =+#REF!+#REF!+#REF!+E25 -> #REF! | G25: =D25-F25 -> #REF! | H25: =MROUND(G25,5) -> #REF! | I25: 311818141 | J25: =SUM(D25:D27)+6500 -> 43125
A26: =+A25+1 -> 20 | B26: H4 | C26: MONIS TSANZIUANE CHIVALE | D26: =+'Folha de salarios'!X29 -> 14225 | E26: =D26*0.01 -> 142.25 | F26: =+#REF!+#REF!+#REF!+E26 -> #REF! | G26: =D26-F26 -> #REF! | H26: =MROUND(G26,5) -> #REF! | I26: 169475394
A27: =+A26+1 -> 21 | B27: H4 | C27: EVELIN NELSON BERNARDO | D27: =+'Folha de salarios'!X30 -> 10955 | E27: =D27*0.01 -> 109.55 | F27: =+#REF!+#REF!+#REF!+E27 -> #REF! | G27: =D27-F27 -> #REF! | H27: =MROUND(G27,5) -> #REF! | I27: 257804370
C29: Total este Pagina | D29: =SUM(D7:D27) -> 346473 | E29: =SUM(E7:E27) -> 3464.73 | F29: =SUM(F7:F27) -> #REF! | G29: =SUM(G7:G27) -> #REF! | H29: =SUM(H7:H27) -> #REF! | J29: =SUM(J7:J27) -> 321348
H33: O Pagador :
A34: ( A ) | C34: Riscar o que nao interessa.
A35: ( B ) | C35: Assinalar com M os trabalhadores de menor idade | H35: 1a Testemunha:
A36: ( C ) | C36: Nao preencher quando se trata de trabalhadores ao dia.
A37: ( D ) | C37: Descontos permitidos por lei | H37: 2a Testemunha :
H42: =#REF! -> #REF!
D45: INSS
D46: =+D29*7% -> 24253.11

Sheet PaySlip
B1: Landco Lda | J1: Landco Lda
B3: Recibo de Vencimento | J3: Recibo de Vencimento
B4: 1 | J4: =+B4 -> 1
B5: Mês de | C5: =+'Folha de salarios'!AG6 -> JANEIRIO | E5: 2025 | J5: Mês de | K5: =+C5 -> JANEIRIO | M5: =+E5 -> 2025
B6: Nome | C6: =+'Folha de salarios'!C10 -> MARCO BEBE GIMO | J6: Nome | K6: =C6 -> MARCO BEBE GIMO
B7: Categoria | C7: =+'Folha de salarios'!G10 -> GERENTE | J7: Categoria | K7: =+C7 -> GERENTE
B9: Vencimento ilíquido | G9: =+'Folha de salarios'!M10 -> 81000 | J9: Vencimento ilíquido | O9: =+G9 -> 81000
B10: Horas Extras | G10: =0 -> 0 | J10: Horas Extras | O10: =G10 -> 0
B11: Ferias | G11: 0 | J11: Ferias | O11: =G11 -> 0
B12: Subsidio Nocturno | G12: 0 | J12: Subsidio Nocturno | O12: 0
E13: SOMA | G13: =SUM(G9:G12) -> 81000 | M13: SOMA | O13: =SUM(O9:O12) -> 81000
C15: Descontos: | K15: Descontos:
D16: IRPS | G16: =+'Folha de salarios'!Z10 -> 10437.5 | L16: IRPS | O16: =+G16 -> 10437.5
D17: INSS | G17: =+G13*0.03 -> 2430 | L17: INSS | O17: =+G17 -> 2430
D18: Sindicato | G18: =+G13*0.01 -> 810 | L18: Sindicato | O18: =+G18 -> 810
D19: V. Adiatado | L19: V. Adiatado | O19: =G19 -> 0
D20: Faltas | L20: Faltas | O20: =G20 -> 0
D21: Ausência | L21: Ausência | O21: =G21 -> 0
D22: Emprestimo | G22: =+'Folha de salarios'!Y10 -> 0 | L22: Emprestimo | O22: =G22 -> 0
E23: SOMA | G23: =SUM(G16:G22) -> 13677.5 | L23: SOMA | O23: =SUM(O16:O22) -> 13677.5
C25: Líquido Pago | G25: =G13-G23 -> 67322.5 | K25: Líquido Pago | O25: =O13-O23 -> 67322.5
E28: Recebi | M28: Recebi
B30: Landco Lda | J30: Landco Lda
B32: Recibo de Vencimento | J32: Recibo de Vencimento
B33: =+B4+1 -> 2 | J33: =+B33 -> 2
B34: Mês de | C34: =+C5 -> JANEIRIO | E34: =+E5 -> 2025 | J34: Mês de | K34: =+C34 -> JANEIRIO | M34: =+E34 -> 2025
B35: Nome | C35: =+'Folha de salarios'!C11 -> ARMINDO QUETANE HOU | J35: Nome | K35: =+C35 -> ARMINDO QUETANE HOU
B36: Categoria | C36: =+'Folha de salarios'!G11 -> GUARDA | J36: Categoria | K36: =+C36 -> GUARDA
B38: Vencimento ilíquido | G38: =+'Folha de salarios'!M11 -> 11336 | J38: Vencimento ilíquido | O38: =+G38 -> 11336
B39: Horas Extras | G39: =+'Folha de salarios'!S11 -> 4251 | J39: Horas Extras | O39: =G39 -> 4251
B40: Ferias | G40: 0 | J40: Ferias | O40: =G40 -> 0
B41: Subsidio Nocturno | G41: =+'Folha de salarios'!O11 -> 1889.3333 | J41: Subsidio Nocturno | O41: =+G41 -> 1889.3333
E42: SOMA | G42: =SUM(G38:G41) -> 17476.333 | M42: SOMA | O42: =SUM(O38:O41) -> 17476.333
C44: Descontos: | K44: Descontos:
D45: IRPS | G45: =+'Folha de salarios'!Z40 -> 0 | L45: IRPS | O45: =+G45 -> 0
D46: INSS | G46: =+G42*0.03 -> 524.29 | L46: INSS | O46: =+G46 -> 524.29
D47: Sindicato | G47: =+G42*0.01 -> 174.76333 | L47: Sindicato | O47: =+G47 -> 174.76333
D48: V. Adiatado | L48: V. Adiatado | O48: =G48 -> 0
D49: Faltas | L49: Faltas | O49: =G49 -> 0
D50: Ausência | L50: Ausência | O50: =G50 -> 0
...
