Workbook

Sheet INCOME
A1: LANDCO INCOME | D1: H1 | E1: =+E49 -> 0 | F1: =+E1/63.25 -> 0
D2: H2 | E2: =+F49 -> 0 | F2: =+E2/63.25 -> 0
D3: H3 | E3: =+G49 -> 0 | F3: =+E3/63.25 -> 0
D4: H4 | E4: =+H49 -> 0 | F4: =+E4/63.25 -> 0
E5: =SUM(E1:E4) -> 0 | F5: =+E5/63.25 -> 0 | G5: =SUM(F1:F4) -> 0
A6: DATE | B6: HOUSE | C6: NAME | D6: ACCOMODATION | E6: H1 | F6: H2 | G6: H3 | H6: H4 | I6: TOTAL MTS | J6: DOLLARS | K6: TOTAL PER MONTH
A7: 45659 | B7: 3 | C7: ALEX | D7: 594297 | E7: 0 | G7: =+D7 -> 594297 | I7: =SUM(E7:H7) -> 594297 | J7: =+D7/63.25 -> 9396 | K7: =SUM(I7:I9) -> 1846127
A8: 45673 | B8: 2 | C8: WARREN STEAD | D8: 958350 | F8: =+D8 -> 958350 | I8: =SUM(E8:H8) -> 958350 | J8: =+D8/63.25 -> 15151.779
A9: 45681 | B9: 3 | C9: ALEX | D9: 293480 | G9: =+D9 -> 293480 | I9: =SUM(E9:H9) -> 293480 | J9: =+D9/63.25 -> 4640
A11: 45713 | B11: 3 | C11: CREDIT IVA H3 - KEITH & SUE X 8 NIGHTS @ 75 | D11: 40200 | G11: =+D11 -> 40200 | I11: =+D11 -> 40200 | J11: =+D11/67 -> 600 | K11: =+I11 -> 40200
A13: 45720 | B13: 3 | C13: ALEX | D13: 751171 | G13: =+D13 -> 751171 | I13: =SUM(E13:H13) -> 751171 | J13: =+D13/63.25 -> 11876.221 | K13: =SUM(D13:D16) -> 2299693
A14: 45740 | B14: 4 | C14: WARREN PAY TRACY SALARY AND RECRUITMENT | D14: =6942*66 -> 458172 | H14: =+D14 -> 458172 | I14: =SUM(E14:H14) -> 458172 | J14: =+D14/66 -> 6942
A15: 45741 | B15: 2 | C15: WARREN STEAD | D15: 958350 | F15: =+D15 -> 958350 | I15: =SUM(E15:H15) -> 958350 | J15: =+D15/63.25 -> 15151.779
A16: 45741 | B16: 3 | C16: ALEX | D16: =2000*66 -> 132000 | G16: =+D16 -> 132000 | I16: =SUM(E16:H16) -> 132000 | J16: =+D16/66 -> 2000
A18: 45763 | B18: 1 | C18: TAFY RECEIVED FROM ROBIN | D18: =6950*67 -> 465650 | E18: =+D18 -> 465650 | J18: 6950 | K18: =SUM(D18:D20) -> 923170
A19: 45763 | B19: 2 | C19: BRENDON 7 DAYS @80 | D19: =560*67 -> 37520 | F19: =+D19 -> 37520 | J19: =7*80 -> 560
A20: 45777 | B20: 3 | C20: KEIVIN PAY TO BANK | D20: =+'[2]Breakdown of Income'!$C$9 -> 420000 | G20: =+D20 -> 420000 | J20: =+G20/63.25 -> 6640.3162
A22: 45800 | B22: 1 | C22: TAFY RECEIVED FROM AANGIE | D22: =5000*62 -> 310000 | E22: =+D22 -> 310000 | J22: 5000 | K22: =SUM(D22:D24) -> 1268350
A24: 45811 | B24: 1 | C24: ALEX | D24: 958350 | G24: =+D24 -> 958350 | J24: =+D24/63.25 -> 15151.779 | K24: =SUM(D24:D26) -> 2865450
A25: 45828 | B25: 4 | C25: WARREN COHEN INVESTMENT | D25: =15000*63.25 -> 948750 | H25: =+D25 -> 948750 | J25: =+D25/63.25 -> 15000
A26: 45829 | B26: 3 | C26: WARREN STEAD | D26: 958350 | F26: =+D26 -> 958350 | J26: =+D26/63.25 -> 15151.779
A28: 45854 | B28: 1 | C28: TAFY RECEIVED FROM ALEX | D28: =+J28*67 -> 335000 | E28: =+D28 -> 335000 | J28: 5000 | K28: =SUM(D28:D291) -> 7882805
A29: 45855 | B29: 4 | C29: ARON ACCOMMODATION IN H4 | D29: =1470*67 -> 98490 | H29: =+D29 -> 98490 | J29: 1470
A31: 45880 | B31: 1 | C31: CREDIT IVA H1 - LESLEY X 6 NIGHTS | D31: =+J31*68 -> 68000 | E31: =+D31 -> 68000 | J31: 1000 | K31: =SUM(D31:D294) -> 7449315
A32: 45894 | B32: 2 | C32: WARREN | D32: =+J32*68 -> 119000 | F32: =+D32 -> 119000 | J32: =1250+500 -> 1750
A34: 45912 | B34: 3 | C34: ALEX | D34: 638900 | G34: =+D34 -> 638900 | I34: =SUM(E34:H34) -> 638900 | J34: =+D34/63.25 -> 10101.186 | K34: =SUM(D34:D37) -> 1641540
A35: 45922 | B35: 4 | C35: ALAIN WARREN | D35: 60720 | H35: =+D35 -> 60720 | J35: =+D35/69 -> 880
A37: 45940 | B37: 2 | C37: WARREN STEAD | D37: =617120+324800 -> 941920 | F37: =+D37 -> 941920 | J37: =+D37/63.25 -> 14892.016 | K37: =SUM(D37:D39) -> 2112970
A38: 45953 | B38: 3 | C38: ALEX TRANSFER TO MONIQUE | D38: 222300 | G38: =57000*3.9 -> 222300 | J38: 3000
A39: 45954 | B39: 4 | C39: WARREN COHEN INVESTMENT | D39: =15000*63.25 -> 948750 | H39: =15000*63.25 -> 948750 | J39: =+H39/63.25 -> 15000
A41: 45979 | B41: 3 | C41: ALEX | D41: 948750 | G41: =+D41 -> 948750 | J41: =+D41/63.25 -> 15000 | K41: =SUM(D41:D44) -> 1522150
A42: 45980 | B42: 2 | C42: BRENDON | D42: =320*70 -> 22400 | F42: =+D42 -> 22400 | J42: 320
A43: 45986 | B43: 1 | C43: TAFY | D43: =551000 -> 551000 | E43: =+D43 -> 551000 | J43: =+D43/63.25 -> 8711.4625
A45: 46007 | B45: 2 | C45: BRENDON | D45: =800*69 -> 55200 | F45: =+D45 -> 55200 | J45: 800
A46: 46020 | B46: 1 | C46: TAFY RE ROBIN | D46: =3000*69 -> 207000 | E46: =+D46 -> 207000 | J46: 3000
A47: 46020 | B47: 3 | C47: REVERSE ALEX TRANSFER TO ALEX ENVELOPE | G47: =+D47 -> 0
A48: 46020 | B48: 4 | C48: WARREN INVESTMENT DOLLAR ACCOUNT | D48: =9000*63.25 -> 569250 | H48: =+D48 -> 569250 | J48: 9000
A50: 46031 | B50: 2 | C50: WARREN STEAD DEP BANK | D50: =SUM('[3]BIM Bank Control Mtn'!$G$15:$G$17) -> 948750 | F50: =+D50 -> 948750 | J50: =+D50/63.25 -> 15000
A51: 46038 | B51: 1 | C51: TAFY | D51: =+J51*67 -> 812375 | E51: =+D51 -> 812375 | J51: =+'[4]LANDCO US$ CASH'!$E$20 -> 12125
A53: 46069 | B53: 1 | C53: TAFY | D53: =+J53*67 -> 335000 | E53: =+D53 -> 335000 | J53: 5000

Sheet RECON
D1: 46054
C3: BALANCE END JAN | D3: INCOME FEB | E3: EXPENSES FEB | F3: TOTAL END FEB
B4: CASA LUZ | C4: 172438.58 | D4: =5000*67 -> 335000 | E4: =+' EXPENSES HOUSE'!L4 -> 204597.69 | F4: =+C4+D4-E4 -> 302840.89 | H4: =+F4-C21 -> -0.0025
B5: CASA AURORA | C5: 727458.65 | E5: =+' EXPENSES HOUSE'!L5 -> 239143.15 | F5: =+C5+D5-E5 -> 488315.5 | H5: =+F5-C22 -> -239143.15
B6: CASA CAJU | C6: 527529.51 | E6: =+' EXPENSES HOUSE'!L6 -> 220170 | F6: =+C6+D6-E6 -> 307359.51 | H6: =+F6-C23 -> -0.0025000001
B7: CASA COCO | C7: 152154.57 | E7: =+' EXPENSES HOUSE'!L7 -> 242759.98 | F7: =+C7+D7-E7 -> -90605.413 | H7: =+F7-C24 -> -0.0058333333
B8: NEGU | C8: 170900 | E8: 0 | F8: =+C8+D8-E8 -> 170900
B9: Total | C9: 1750481.3 | D9: =SUM(D4:D8) -> 335000 | E9: =SUM(E4:E8) -> 906670.82 | F9: =SUM(F4:F8) -> 1178810.5
B11: SHAREHOLDERS | D11: ADD INCOME | G11: PETTY CASH | I11: BANK/PRE-PAID & $
C12: =+C9 -> 1750481.3 | F12: OPEN BALANCE | G12: 557664.46 | I12: 1192816.6 | K12: =+C12-G12-I12 -> 0.2433
C13: =+D9 -> 335000 | F13: INCOME | G13: =5000*67 -> 335000 | K13: =+C13-G13-I13 -> 0
F14: ADD INCOME | K14: =+C14-G14-I14 -> 0
K15: =+C15-G15-I15 -> 0
B16: =+E9 -> 906670.82 | F16: PAYMENTS | H16: =+'[5]LANDCO MET CASH'!$F$8 -> 204957.5 | J16: =+'[6]BIM Bank Control Mtn'!$J$5-3464.73+'[6]Petty cash '!$G$7+'[6]Pre-paid'!$G$7 -> 693950.82 | K16: =+B16-H16-J16 -> 7762.5
B17: =+F9 -> 1178810.5 | F17: BALANCE | H17: =+'[5]LANDCO MET CASH'!$F$9+335000 -> 687706.96 | J17: =+'[6]BIM Bank Control USD'!$I$7+'[6]BIM Bank Control Mtn'!$J$6+'[6]Petty cash '!$G$8+'[6]Pre-paid'!$G$8 -> 498865.79 | K17: =+B17-H17-J17 -> -7762.2617
B18: =SUM(B12:B17) -> 2085481.3 | C18: =SUM(C12:C17) -> 2085481.3 | D18: =SUM(D13:D17) -> 0 | E18: =SUM(E13:E17) -> 0 | G18: =SUM(G12:G17) -> 892664.46 | H18: =SUM(H12:H17) -> 892664.46 | I18: =SUM(I12:I17) -> 1192816.6 | J18: =SUM(J12:J17) -> 1192816.6
C19: =+B18-C18 -> 0 | H19: =+G18-H18 -> -0.0025000002 | J19: =+I18-J18 -> -0.0025000002 | K19: =SUM(K12:K17) -> 0.4816
B20: SHAREHOLDERS ACCOUNTS END FEB | D20: 63.25 | F20: END FEB
B21: CASA LUZ | C21: =+[7]SUMMERY!$E$19 -> 302840.9 | D21: =+C21/$D$20 -> 4787.9984 | F21: BANK MTS & $ | G21: =+J17 -> 498865.79 | I21: RECEIVED TO REPLAY BURGARY
B22: CASA AURORA | C22: =+'[8] SUMMERY '!$F$19 -> 727458.65 | D22: =+C22/$D$20 -> 11501.323 | F22: CASH | G22: =+'[5]LANDCO MET CASH'!$F$9 -> 352706.96 | H22: =SUM(G22:G23) -> 687706.96 | I22: WARREN STEAD | J22: =1375 -> 1375 | K22: =+J22*70 -> 96250
B23: CASA CAJU | C23: =+[9]SUMMERY!$F$19 -> 307359.51 | D23: =+C23/$D$20 -> 4859.4389 | F23: DOLLAR CASH | G23: =+'[5]LANDCO US$ CASH'!$F$11 -> 335000 | I23: TAFY | J23: 1375 | K23: =+J23*70 -> 96250 | L23: received Jan
B24: CASA COCO | C24: =+'[10]SUMMERY '!$F$19 -> -90605.408 | D24: =+C24/$D$20 -> -1432.4966 | I24: ALEX | J24: 0 | K24: =+J24*69 -> 0
B25: NEGO | C25: 170900 | D25: =+C25/$D$20 -> 2701.9763 | I25: WARREN COHEN | J25: 0
C26: =SUM(C21:C25) -> 1417953.7 | D26: =SUM(D21:D25) -> 22418.24 | G26: =SUM(G21:G25) -> 1186572.8
I27: RECEIVED IN METS | K27: =SUM(K22:K25) -> 192500
I28: PETTY CASH | K28: -140925.9
G29: =+G26-F9 -> 7762.2617 | I29: ANDRISA CASH | K29: -70000
I30: NEGU | K30: -170900
J31: =SUM(J22:J30) -> 2750 | K31: =SUM(K27:K30) -> -189325.9

Sheet  EXPENSES
A1: LANDCO BANK EXPENSES | F1: H1 | G1: H2 | I1: H3 | J1: H4
C2: BANK PAYMENTS | E2: =SUM(E8:E52) -> 693950.82
C3: CASH PAYMENTS | E3: =SUM(E59:E67) -> 212720 | W3: =+#REF!-E2 -> #REF!
C4: TOTAL | E4: =SUM(E2:E3) -> 906670.82 | G4: =+E4/4 -> 226667.71 | H4: =+G4/63.25 -> 3583.6791
F5: SHARED EXPENSES
A6: DATE | B6: SUPPLER | C6: DISCRIPTION | E6: TOTAL | F6: LC SALARIES & WAGES | G6: CASUAL WORKERS AND ALLOWANCE | H6: ADVANCE SALARIES INCLUDED IN TOTAL SALRIES | I6: OFFICE AND BANK CHARGES | J6: ADMIN CHARGES (BDO & ANDRISA ) | K6: GAS AND ELECTRISITY | L6: MAINTENANCE GENERAL | M6: MAINTENANCE GARDEN & POOL | N6: SMALL TOOLS | O6: EQUIPMENT | P6: MAINTENANCE VEHICLES | Q6: INSURANCE & LICENSE | R6: DIESEL AND PETROL | S6: HOUSE KEEPING | T6: MARINTINE & MUNICIPAL TAXES IPRA &TAE | U6: COMMUNITY | V6: EXPENSES LUZ | W6: EXPENSES AURORA | X6: EXPENSES CAJU | Y6: EXPENSES COCO | Z6: SUSPENCE | AA6: BALANCE
C7: Bank expenses
A8: 46055 | B8: Leave | C8: Salaries & Wages | E8: 10987.2 | H8: =+E8 -> 10987.2 | AA8: =SUM(F8:Z8) -> 10987.2 | AB8: BANK | AC8: =+E8-AA8 -> 0
A9: 46055 | B9: Bank Charges | C9: Office expenses | E9: 7 | I9: =+E9 -> 7 | AA9: =SUM(F9:Z9) -> 7 | AB9: BANK | AC9: =+E9-AA9 -> 0
A10: 46055 | B10: Quimical swimming pools | C10: Pool Maintenance | E10: 905 | M10: =+E10 -> 905 | AA10: =SUM(F10:Z10) -> 905 | AB10: BANK | AC10: =+E10-AA10 -> 0
A11: 46055 | B11: Quimical swimming pools | C11: Pool Maintenance | E11: 1519.6 | M11: =+E11 -> 1519.6 | AA11: =SUM(F11:Z11) -> 1519.6 | AB11: BANK | AC11: =+E11-AA11 -> 0
A12: 46055 | B12: Bank Charges | C12: Office expenses | E12: 7 | I12: =+E12 -> 7 | AA12: =SUM(F12:Z12) -> 7 | AB12: BANK | AC12: =+E12-AA12 -> 0
A13: 46055 | B13: Advance | C13: Salaries & Wages | E13: 1000 | H13: =+E13 -> 1000 | AA13: =SUM(F13:Z13) -> 1000 | AB13: BANK | AC13: =+E13-AA13 -> 0
A14: 46055 | B14: Bank Charges | C14: Office expenses | E14: 7 | I14: =+E14 -> 7 | AA14: =SUM(F14:Z14) -> 7 | AB14: BANK | AC14: =+E14-AA14 -> 0
A15: 46057 | B15: Union Fee | C15: Salaries & Wages Jan | AA15: =SUM(F15:Z15) -> 0 | AB15: BANK | AC15: =+E15-AA15 -> 0
B16: Union Fee | C16: Salaries & Wages Feb | E16: 3512.26 | H16: 3512.26 | AA16: =SUM(F16:Z16) -> 3512.26 | AB16: BANK | AC16: =+E16-AA16 -> 0
A17: 46057 | B17: Bank Charges | C17: Office expenses | E17: 7 | I17: =+E17 -> 7 | AA17: =SUM(F17:Z17) -> 7 | AB17: BANK | AC17: =+E17-AA17 -> 0
A18: 46062 | B18: Advance | C18: Salaries & Wages | E18: 3500 | H18: =+E18 -> 3500 | AA18: =SUM(F18:Z18) -> 3500 | AB18: BANK | AC18: =+E18-AA18 -> 0
A19: 46062 | B19: Bank Charges | C19: Office expenses | E19: 7 | I19: =+E19 -> 7 | AA19: =SUM(F19:Z19) -> 7 | AB19: BANK | AC19: =+E19-AA19 -> 0
A20: 46063 | B20: Electrisity | C20: Gas& Eletrisity | E20: 58424.49 | K20: =+E20 -> 58424.49 | AA20: =SUM(F20:Z20) -> 58424.49 | AB20: BANK | AC20: =+E20-AA20 -> 0
A21: 46063 | B21: Bank Charges | C21: Office expenses | E21: 7 | I21: =+E21 -> 7 | AA21: =SUM(F21:Z21) -> 7 | AB21: BANK | AC21: =+E21-AA21 -> 0
A22: 46067 | B22: Diesel Generator | C22: General Maintenance | E22: 4263 | R22: =+E22 -> 4263 | AA22: =SUM(F22:Z22) -> 4263 | AB22: BANK | AC22: =+E22-AA22 -> 0
A23: 46071 | B23: Advance | C23: Salaries & Wages | E23: 500 | H23: =+E23 -> 500 | AA23: =SUM(F23:Z23) -> 500 | AB23: BANK | AC23: =+E23-AA23 -> 0
A24: 46071 | B24: Bank Charges | C24: Office expenses | E24: 7 | I24: =+E24 -> 7 | AA24: =SUM(F24:Z24) -> 7 | AB24: BANK | AC24: =+E24-AA24 -> 0
A25: 46071 | B25: Accounting | C25: Accounting fee Feb | E25: 37386.8 | J25: =+E25 -> 37386.8 | AA25: =SUM(F25:Z25) -> 37386.8 | AB25: BANK | AC25: =+E25-AA25 -> 0
A26: 46071 | B26: Bank Charges | C26: Office expenses | E26: 7 | I26: =+E26 -> 7 | AA26: =SUM(F26:Z26) -> 7 | AB26: BANK | AC26: =+E26-AA26 -> 0
A27: 46072 | B27: Admin Fee | C27: Admin Cost | E27: 146740 | J27: =+E27 -> 146740 | AA27: =SUM(F27:Z27) -> 146740 | AB27: BANK | AC27: =+E27-AA27 -> 0
A28: 46072 | B28: Bank Charges | C28: Office expenses | E28: 7 | I28: 7 | AA28: =SUM(F28:Z28) -> 7 | AB28: BANK | AC28: =+E28-AA28 -> 0
A29: 46076 | B29: Gas Jan | C29: Gas& Eletrisity | E29: 4470.61 | K29: =+E29 -> 4470.61 | AA29: =SUM(F29:Z29) -> 4470.61 | AB29: BANK | AC29: =+E29-AA29 -> 0
A30: 46076 | B30: Bank Charges | C30: Office expenses | E30: 7 | I30: 7 | AA30: =SUM(F30:Z30) -> 7 | AB30: BANK | AC30: =+E30-AA30 -> 0
A31: 46076 | B31: House Kepping Towel Duck | C31: House Keping | E31: 20787.2 | Y31: =+E31 -> 20787.2 | AA31: =SUM(F31:Z31) -> 20787.2 | AB31: BANK | AC31: =+E31-AA31 -> 0
A32: 46076 | B32: Bank Charges | C32: Office expenses | E32: 120 | I32: 120 | AA32: =SUM(F32:Z32) -> 120 | AB32: BANK | AC32: =+E32-AA32 -> 0
A33: 46076 | B33: SIM R SEG | C33: INSURANCE JET SKI AND TRAILER | E33: 1409.68 | Q33: =+E33 -> 1409.68 | AA33: =SUM(F33:Z33) -> 1409.68 | AB33: BANK | AC33: =+E33-AA33 -> 0
A34: 46076 | B34: Revisao de Extintores | C34: MAINTENANCE | E34: 21558.6 | L34: =+E34 -> 21558.6 | AA34: =SUM(F34:Z34) -> 21558.6 | AB34: BANK | AC34: =+E34-AA34 -> 0
A35: 46076 | B35: Bank Charges | C35: Office expenses | E35: 7 | I35: 7 | AA35: =SUM(F35:Z35) -> 7 | AB35: BANK | AC35: =+E35-AA35 -> 0
A36: 46078 | B36: Dolar to Mets | C36: SUSPENSE | AA36: =SUM(F36:Z36) -> 0 | AB36: BANK | AC36: =+E36-AA36 -> 0
A37: 46078 | B37: Salario Feb | C37: SALARIES FEB | E37: 310752.26 | F37: =+'[1]Folha de salarios'!$AH$10 -> 169068.42 | V37: =+'[1]Folha de salarios'!$AH$18 -> 35109.333 | W37: =+'[1]Folha de salarios'!$AH$21 -> 65199.917 | X37: =+'[1]Folha de salarios'!$AH$25 -> 38723.333 | Y37: =+'[1]Folha de salarios'!$AH$28 -> 43125 | AA37: =SUM(F37:Z37) -> 351226 | AB37: BANK | AC37: =+E37-AA37 -> -40473.74
A38: 46078 | B38: Bank Charges | C38: Office expenses | E38: 254 | I38: =+E38 -> 254 | AA38: =SUM(F38:Z38) -> 254 | AB38: BANK | AC38: =+E38-AA38 -> 0
A39: 46079 | B39: Cleaning supplies | C39: HOUSE KEEPING | E39: 755 | S39: =+E39 -> 755 | AA39: =SUM(F39:Z39) -> 755 | AB39: BANK | AC39: =+E39-AA39 -> 0
A40: 46079 | B40: Eletrical material | C40: General Maintenance | E40: 1465 | L40: =+E40 -> 1465 | AA40: =SUM(F40:Z40) -> 1465 | AB40: BANK | AC40: =+E40-AA40 -> 0
...

Sheet  EXPENSES HOUSE
A1: LANDCO BANK EXPENSES PER HOUSE
C3: SHARED | D3: SALARIES | E3: EXPENSES BY GUESTS | F3: BOAT SKIPPERS CLEANING | G3: BOAT CLEANING MATERIAL | H3: HOUSE KEEPING | I3: HOUSEHOLD EQUIPMENT | J3: PETROL & BATTERY | K3: TOTAL PERSONAL | L3: TOTAL | M3: SHARED EXPENSES | O3: SHARED
B4: CASA LUZ | C4: =+O19 -> 162772.73 | D4: =+' EXPENSES'!V37+' EXPENSES'!V42 -> 36513.707 | F4: 400 | G4: =+' EXPENSES'!V65 -> 3881.25 | H4: =+' EXPENSES'!V49 -> 1030 | K4: =SUM(D4:J4) -> 41824.957 | L4: =+C4+K4 -> 204597.69 | M4: SALARIES & WAGES | N4: 320301.15 | O4: =+N4/4 -> 80075.288
B5: CASA AURORA | C5: =+C4 -> 162772.73 | D5: =+' EXPENSES'!W37+' EXPENSES'!W42 -> 67807.913 | F5: 800 | G5: =+' EXPENSES'!W65 -> 7762.5 | I5: =+' EXPENSES'!W87 -> 0 | K5: =SUM(D5:J5) -> 76370.413 | L5: =+C5+K5 -> 239143.15 | M5: CASUAL WORKERS AND FOOD ALLOWANCE | N5: 21000 | O5: =+N5/4 -> 5250
B6: CASA CAJU | C6: =+C5 -> 162772.73 | D6: =+' EXPENSES'!X37+' EXPENSES'!X42 -> 40272.267 | F6: 1600 | G6: =+' EXPENSES'!X65 -> 15525 | H6: =+' EXPENSES'!X52 -> 0 | J6: =+' EXPENSES'!X47+' EXPENSES'!X75 -> 0 | K6: =SUM(D6:J6) -> 57397.267 | L6: =+C6+K6 -> 220170 | M6: OFFICE AND BANK CHARGES | N6: 3946 | O6: =+N6/4 -> 986.5
B7: CASA COCO | C7: =+C6 -> 162772.73 | D7: =+' EXPENSES'!Y37+' EXPENSES'!Y42 -> 44850 | F7: 400 | G7: =+' EXPENSES'!Y65 -> 3881.25 | I7: =+' EXPENSES'!Y46+' EXPENSES'!Y31 -> 30856 | K7: =SUM(D7:J7) -> 79987.25 | L7: =+C7+K7 -> 242759.98 | M7: ADMIN CHARGES (BDO & ANDRISA ENS ) | N7: 184126.8 | O7: =+N7/4 -> 46031.7
L8: =SUM(L4:L7) -> 906670.82 | M8: GAS AND ELECTRISITY | N8: 62895.1 | O8: =+N8/4 -> 15723.775
L9: =+' EXPENSES'!E4 -> 906670.82 | M9: MAINTENANCE GENERAL | N9: 24273.6 | O9: =+N9/4 -> 6068.4
L10: =+L8-L9 -> 0 | M10: MAINTENANCE GARDEN & POOL | N10: 2424.6 | O10: =+N10/4 -> 606.15
M11: SMALL TOOLS | N11: 0 | O11: =+N11/4 -> 0
L12: =+L9/63.25/4 -> 3583.6791 | M12: EQUIPMENT PRESSURE PUMP X 2 | N12: 0 | O12: =+N12/4 -> 0
M13: MAINTENANCE VEHICLES | N13: 0 | O13: =+N13/4 -> 0
M14: INSURANCE & LICENSE | N14: 5125.68 | O14: =+N14/4 -> 1281.42
M15: DIESEL AND PETROL | N15: 14263 | O15: =+N15/4 -> 3565.75
M16: HOUSE KEEPING | N16: 12735 | O16: =+N16/4 -> 3183.75
M17: MARINTINE & MUNICIPAL TAXES IPRA &TAE | N17: 0 | O17: =+N17/4 -> 0
M18: COMMUNITY DONATION | N18: 0 | O18: =+N18/4 -> 0
N19: =SUM(N4:N18) -> 651090.93 | O19: =SUM(O4:O18) -> 162772.73
M24: EXPENSES LUZ | N24: =+' EXPENSES'!V91 -> 41824.957 | O24: =+N24 -> 41824.957
M25: EXPENSES AURORA | N25: =+' EXPENSES'!E111 -> 76370.413 | O25: =+N25 -> 76370.413
M26: EXPENSES CAJU | N26: =+' EXPENSES'!E112 -> 57397.267 | O26: =+N26 -> 57397.267
M27: EXPENSES COCO | N27: =+' EXPENSES'!Y91 -> 79987.25 | O27: =+N27 -> 79987.25
N28: =+N19+N24+N25+N26+N27 -> 906670.82
N30: =+' EXPENSES'!E115 -> 906674.92
N31: =+N28-N30 -> -4.1

Sheet MONTHLY FOR THE YEAR
A1: LANDCO EXPENSES
B2: MONTH | C2: EXPENSES | D2: 63.25
B4: 46023 | C4: =+' EXPENSES'!E115 -> 906674.92 | D4: =+C4/$D$2 -> 14334.781
B5: 46055 | D5: =+C5/$D$2 -> 0
B6: 46087 | D6: =+C6/$D$2 -> 0
B7: 46119 | D7: =+C7/$D$2 -> 0
B8: 46151 | D8: =+C8/$D$2 -> 0
B9: 46183 | D9: =+C9/$D$2 -> 0
B10: 46215 | D10: =+C10/$D$2 -> 0
B11: 46247 | D11: =+C11/$D$2 -> 0
B12: 46279 | D12: =+C12/$D$2 -> 0
B13: 46311 | D13: =+C13/$D$2 -> 0
B14: 46343 | D14: =+C14/$D$2 -> 0
B15: 46375 | D15: =+C15/$D$2 -> 0
C16: =SUM(C4:C15) -> 906674.92 | D16: =SUM(D4:D15) -> 14334.781
B18: AVERAGE | C18: =+C16/9 -> 100741.66 | D18: =+D16/9 -> 1592.7535
