Workbook

Sheet INCOME
A1: LANDCO INCOME | D1: H1 | E1: =+#REF! -> #REF! | F1: =+E1/63.25 -> #REF!
D2: H2 | E2: =+#REF! -> #REF! | F2: =+E2/63.25 -> #REF!
D3: H3 | E3: =+#REF! -> #REF! | F3: =+E3/63.25 -> #REF!
D4: H4 | E4: =+#REF! -> #REF! | F4: =+E4/63.25 -> #REF!
E5: =SUM(E1:E4) -> #REF! | F5: =+E5/63.25 -> #REF! | G5: =SUM(F1:F4) -> #REF!
A6: DATE | B6: HOUSE | C6: NAME | D6: ACCOMODATION | E6: H1 | F6: H2 | G6: H3 | H6: H4 | I6: TOTAL MTS | J6: DOLLARS | K6: TOTAL PER MONTH
A7: 46097 | B7: 1 | C7: TAFY ELIANA | D7: 38400 | E7: 38400 | J7: =+D7/63.25 -> 607.11462
A8: 46097 | B8: 4 | C8: WARREN COHEN INVESTMENT | D8: =+J8*67 -> 1407000 | H8: =21000*63.25 -> 1328250 | J8: =+H8/63.25 -> 21000

Sheet RECON
D1: 46082
C3: BALANCE END FEB | D3: INCOME MARCH | E3: EXPENSES MARCH | F3: TOTAL END MARCH
B4: CASA LUZ | C4: 307122.14 | D4: 38400 | E4: =+' EXPENSES HOUSE'!L4 -> 162772.73 | F4: =+C4+D4-E4 -> 182749.41 | H4: =+F4-C21 -> -124372.74
B5: CASA AURORA | C5: 488315.5 | E5: =+' EXPENSES HOUSE'!L5 -> #REF! | F5: =+C5+D5-E5 -> #REF! | H5: =+F5-C22 -> #REF!
B6: CASA CAJU | C6: 307359.51 | E6: =+' EXPENSES HOUSE'!L6 -> #REF! | F6: =+C6+D6-E6 -> #REF! | H6: =+F6-C23 -> #REF!
B7: CASA COCO | C7: -86324.163 | D7: =21000*63.25 -> 1328250 | E7: =+' EXPENSES HOUSE'!L7 -> 173272.73 | F7: =+C7+D7-E7 -> 1068653.1 | H7: =+F7-C24 -> 1154977.3
B8: NEGU | C8: 170900 | F8: =+C8 -> 170900
B9: Total | C9: 1187373 | D9: =SUM(D4:D8) -> 1366650 | E9: =SUM(E4:E8) -> #REF! | F9: =SUM(F4:F8) -> #REF!
B11: SHAREHOLDERS | D11: ADD INCOME | G11: PETTY CASH | I11: BANK/PRE-PAID & $
C12: =+C9 -> 1187373 | F12: OPEN BALANCE | G12: 557664.46 | I12: 1192816.6 | K12: =+C12-G12-I12 -> -563108.08
C13: =+D9 -> 1366650 | F13: INCOME | G13: =5000*67 -> 335000 | K13: =+C13-G13-I13 -> 1031650
F14: ADD INCOME | K14: =+C14-G14-I14 -> 0
K15: =+C15-G15-I15 -> 0
B16: =+E9 -> #REF! | F16: PAYMENTS | H16: =+'[1]LANDCO MET CASH'!$F$8 -> 212720 | J16: =+'[2]BIM Bank Control Mtn'!$J$5-3464.73+'[2]Petty cash '!$G$7+'[2]Pre-paid'!$G$7 -> 693950.82 | K16: =+B16-H16-J16 -> #REF!
B17: =+F9 -> #REF! | F17: BALANCE | H17: =+'[1]LANDCO MET CASH'!$F$9+335000 -> 679944.46 | J17: =+'[2]BIM Bank Control USD'!$I$7+'[2]BIM Bank Control Mtn'!$J$6+'[2]Petty cash '!$G$8+'[2]Pre-paid'!$G$8 -> 498865.79 | K17: =+B17-H17-J17 -> #REF!
B18: =SUM(B12:B17) -> #REF! | C18: =SUM(C12:C17) -> 2554023 | D18: =SUM(D13:D17) -> 0 | E18: =SUM(E13:E17) -> 0 | G18: =SUM(G12:G17) -> 892664.46 | H18: =SUM(H12:H17) -> 892664.46 | I18: =SUM(I12:I17) -> 1192816.6 | J18: =SUM(J12:J17) -> 1192816.6
C19: =+B18-C18 -> #REF! | H19: =+G18-H18 -> -0.0025000002 | J19: =+I18-J18 -> -0.0025000002 | K19: =SUM(K12:K17) -> #REF!
B20: SHAREHOLDERS ACCOUNTS END MARCH | D20: 63.25 | F20: END FEB
B21: CASA LUZ | C21: =+[3]SUMMERY!$E$19 -> 307122.15 | D21: =+C21/$D$20 -> 4855.6861 | F21: BANK MTS & $ | G21: =+J17 -> 498865.79 | I21: RECEIVED TO REPLAY BURGARY
B22: CASA AURORA | C22: =+'[4] SUMMERY '!$F$19 -> 488315.5 | D22: =+C22/$D$20 -> 7720.4032 | F22: CASH | G22: =+'[1]LANDCO MET CASH'!$F$9 -> 344944.46 | H22: =SUM(G22:G23) -> 679944.46 | I22: WARREN STEAD | J22: =1375 -> 1375 | K22: =+J22*70 -> 96250
B23: CASA CAJU | C23: =+[5]SUMMERY!$F$19 -> 307359.51 | D23: =+C23/$D$20 -> 4859.4389 | F23: DOLLAR CASH | G23: =+'[1]LANDCO US$ CASH'!$F$11 -> 335000 | I23: TAFY | J23: 1375 | K23: =+J23*70 -> 96250 | L23: received Jan
B24: CASA COCO | C24: =+'[6]SUMMERY '!$F$19 -> -86324.158 | D24: =+C24/$D$20 -> -1364.8088 | I24: ALEX | J24: 0 | K24: =+J24*69 -> 0
B25: NEGO | C25: 170900 | D25: =+C25/$D$20 -> 2701.9763 | I25: WARREN COHEN | J25: 0
C26: =SUM(C21:C25) -> 1187373 | D26: =SUM(D21:D25) -> 18772.696 | G26: =SUM(G21:G25) -> 1178810.3
I27: RECEIVED IN METS | K27: =SUM(K22:K25) -> 192500
I28: PETTY CASH | K28: -140925.9
G29: =+G26-F9 -> #REF! | I29: ANDRISA CASH | K29: -70000
I30: NEGU | K30: -170900
J31: =SUM(J22:J30) -> 2750 | K31: =SUM(K27:K30) -> -189325.9

Sheet  EXPENSES
A1: LANDCO BANK EXPENSES | F1: H1 | G1: H2 | I1: H3 | J1: H4
C2: BANK PAYMENTS | E2: =SUM(E7:E54) -> 1060728
C3: CASH PAYMENTS | E3: =SUM(E55:E68) -> 99920 | W3: =+#REF!-E2 -> #REF!
C4: TOTAL | E4: =SUM(E2:E3) -> 1160648 | G4: =+E4/4 -> 290161.99 | H4: =+G4/63.25 -> 4587.5414
F5: SHARED EXPENSES
A6: DATE | B6: SUPPLER | C6: DISCRIPTION | E6: TOTAL | F6: LC SALARIES & WAGES | G6: CASUAL WORKERS AND ALLOWANCE | H6: ADVANCE SALARIES INCLUDED IN TOTAL SALRIES | I6: OFFICE AND BANK CHARGES | J6: ADMIN CHARGES (BDO & ANDRISA ) | K6: GAS AND ELECTRISITY | L6: MAINTENANCE GENERAL | M6: MAINTENANCE GARDEN & POOL | N6: SMALL TOOLS | O6: EQUIPMENT | P6: MAINTENANCE VEHICLES | Q6: INSURANCE & LICENSE | R6: DIESEL AND PETROL | S6: HOUSE KEEPING | T6: MARINTINE & MUNICIPAL TAXES IPRA &TAE | U6: COMMUNITY | V6: EXPENSES LUZ | W6: EXPENSES AURORA | X6: EXPENSES CAJU | Y6: EXPENSES COCO | Z6: SUSPENCE | AA6: BALANCE
A7: 46083 | B7: JELSON | C7: SALARIES & WAGES | E7: 5000 | H7: =+E7 -> 5000 | AA7: =SUM(F7:Z7) -> 5000 | AB7: BANK | AC7: =+E7-AA7 -> 0
A8: 46083 | B8: BANK CHARGES | C8: BANK CHARGES | E8: 7 | I8: =+E8 -> 7 | AA8: =SUM(F8:Z8) -> 7 | AB8: BANK | AC8: =+E8-AA8 -> 0
A9: 46086 | B9: EMILIO ADVANCE | C9: SALARIES & WAGES | E9: 2300 | H9: =+E9 -> 2300 | AA9: =SUM(F9:Z9) -> 2300 | AB9: BANK | AC9: =+E9-AA9 -> 0
A10: 46086 | B10: BANK CHARGES | C10: BANK CHARGES | E10: 7 | I10: =+E10 -> 7 | AA10: =SUM(F10:Z10) -> 7 | AB10: BANK | AC10: =+E10-AA10 -> 0
A11: 46086 | B11: CALDERON ADVANCE | C11: SALARIES & WAGES | E11: 1500 | H11: =+E11 -> 1500 | AA11: =SUM(F11:Z11) -> 1500 | AB11: BANK | AC11: =+E11-AA11 -> 0
A12: 46086 | B12: BANK CHARGES | C12: BANK CHARGES | E12: 120 | I12: =+E12 -> 120 | AA12: =SUM(F12:Z12) -> 120 | AB12: BANK | AC12: =+E12-AA12 -> 0
A13: 46090 | B13: VARNISH | C13: GENERAL EXPENSES | E13: 3328 | L13: =+E13 -> 3328 | AA13: =SUM(F13:Z13) -> 3328 | AB13: BANK | AC13: =+E13-AA13 -> 0
A14: 46090 | B14: DIESEL MMR0998 | C14: MOTOR VEHICLE LANDCO | E14: 7384.37 | R14: =+E14 -> 7384.37 | AA14: =SUM(F14:Z14) -> 7384.37 | AB14: BANK | AC14: =+E14-AA14 -> 0
A15: 46090 | B15: TOILET PAPER | C15: HOUSE KEEPING | E15: 5245 | S15: =+E15 -> 5245 | AA15: =SUM(F15:Z15) -> 5245 | AB15: BANK | AC15: =+E15-AA15 -> 0
A16: 46090 | B16: BANK CHARGES | C16: BANK CHARGES SINDICATO BEB | E16: 7 | I16: =+E16 -> 7 | AA16: =SUM(F16:Z16) -> 7 | AB16: BANK | AC16: =+E16-AA16 -> 0
A17: 46092 | B17: ELECTRICITY | C17: GAS & ELECTRISITY | E17: 51111.88 | AA17: =SUM(F17:Z17) -> 0 | AB17: BANK | AC17: =+E17-AA17 -> 51111.88
A18: 46092 | B18: BANK CHARGES | C18: BANK CHARGES | E18: 7 | I18: =+E18 -> 7 | AA18: =SUM(F18:Z18) -> 7 | AB18: BANK | AC18: =+E18-AA18 -> 0
A19: 46092 | B19: IRPS | C19: IRPS DIFFERENCE | E19: 129.49 | H19: =+E19 -> 129.49 | AA19: =SUM(F19:Z19) -> 129.49 | AB19: BANK | AC19: =+E19-AA19 -> 0
A20: 46097 | B20: CHLOOR | C20: SWIMMING POOL CHEMICALS | E20: 8710 | M20: =+E20 -> 8710 | AA20: =SUM(F20:Z20) -> 8710 | AB20: BANK | AC20: =+E20-AA20 -> 0
A21: 46097 | B21: PLASTIC DE LUXO | C21: HOUSE KEEPING | E21: 1290 | S21: =+E21 -> 1290 | AA21: =SUM(F21:Z21) -> 1290 | AB21: BANK | AC21: =+E21-AA21 -> 0
A22: 46098 | B22: CARTO DEBITO | C22: BANK CHARGES | E22: 600 | I22: =+E22 -> 600 | AA22: =SUM(F22:Z22) -> 600 | AB22: BANK | AC22: =+E22-AA22 -> 0
A23: 46099 | B23: ACCOUNTING | C23: ADMIN AND ACCOUNTING | E23: 37386 | I23: \ | J23: =+E23 -> 37386 | AA23: =SUM(F23:Z23) -> 37386 | AB23: BANK | AC23: =+E23-AA23 -> 0
A24: 46099 | B24: BANK CHARGES | C24: BANK CHARGES | E24: 7 | I24: =+E24 -> 7 | AA24: =SUM(F24:Z24) -> 7 | AB24: BANK | AC24: =+E24-AA24 -> 0
A25: 46099 | B25: IMPRA | C25: INSURANCE JETSKI | E25: 1409.68 | Q25: =+E25 -> 1409.68 | AA25: =SUM(F25:Z25) -> 1409.68 | AB25: BANK | AC25: =+E25-AA25 -> 0
A26: 46099 | B26: IMPRA | C26: INSURANCE TRAILER | E26: 1409.68 | Q26: =+E26 -> 1409.68 | AA26: =SUM(F26:Z26) -> 1409.68 | AB26: BANK | AC26: =+E26-AA26 -> 0
A27: 46100 | B27: BALDE PARA CONSTRUTOR | C27: GENERAL EXPENSES | E27: 788 | L27: =+E27 -> 788 | AA27: =SUM(F27:Z27) -> 788 | AB27: BANK | AC27: =+E27-AA27 -> 0
A28: 46100 | B28: CLEANING MATERIAL | C28: HOUSE KEEPING | E28: 3330 | S28: =+E28 -> 3330 | AA28: =SUM(F28:Z28) -> 3330 | AB28: BANK | AC28: =+E28-AA28 -> 0
A29: 46100 | B29: BATTERY PRADO H4 | C29: MOTOR VEHICLES EXPENSES | E29: 10500 | Y29: =+E29 -> 10500 | AA29: =SUM(F29:Z29) -> 10500 | AB29: BANK | AC29: =+E29-AA29 -> 0
A30: 46100 | B30: SEALER H3 | C30: GENERAL EXPENSES | E30: 5688 | X30: =+E30 -> 5688 | AA30: =SUM(F30:Z30) -> 5688 | AB30: BANK | AC30: =+E30-AA30 -> 0
A31: 46100 | B31: BANK CHARGES | C31: BANK CHARGES | E31: 7 | I31: =+E31 -> 7 | AA31: =SUM(F31:Z31) -> 7 | AB31: BANK | AC31: =+E31-AA31 -> 0
A32: 46104 | B32: PETTY CASH | C32: SUSPENSE | E32: 18889.39 | Z32: =+E32 -> 18889.39 | AA32: =SUM(F32:Z32) -> 18889.39 | AB32: BANK | AC32: =+E32-AA32 -> 0
A33: 46106 | B33: SALARY MARCH | C33: SALARIES & WAGES | E33: 305089.85 | F33: 164821 | V33: 34870.88 | W33: 58534 | X33: 36625 | Y33: 43125 | AA33: =SUM(F33:Z33) -> 337975.88 | AB33: BANK | AC33: =+E33-AA33 -> -32886.03 | AD33: =+#REF! -> #REF!
A34: 46106 | B34: BANK CHARGES | C34: BANK CHARGES | E34: 257 | I34: =+E34 -> 257 | AA34: =SUM(F34:Z34) -> 257 | AB34: BANK | AC34: =+E34-AA34 -> 0
A35: 46106 | B35: ADMIN FEE | C35: ACCOUNTING AND ADMIN | E35: 146740 | J35: =+E35 -> 146740 | AA35: =SUM(F35:Z35) -> 146740 | AB35: BANK | AC35: =+E35-AA35 -> 0
A36: 46107 | B36: LIGHTS OUTSIDE | C36: GENERAL MAITENANCE | E36: 1440 | L36: =+E36 -> 1440 | AA36: =SUM(F36:Z36) -> 1440 | AB36: BANK | AC36: =+E36-AA36 -> 0
A37: 46107 | B37: SINDICATO | C37: SALARIES & WAGES | E37: 3379.76 | H37: =+E37 -> 3379.76 | AA37: =SUM(F37:Z37) -> 3379.76 | AB37: BANK | AC37: =+E37-AA37 -> 0
A38: 46108 | B38: SOAP, JAVEL | C38: HOUSE KEEPING | E38: 5430 | S38: =+E38 -> 5430 | AA38: =SUM(F38:Z38) -> 5430 | AB38: BANK | AC38: =+E38-AA38 -> 0
A39: 46108 | B39: TRANSFER DOLLARS TO METICAIS | C39: SUSPENSE | AA39: =SUM(F39:Z39) -> 0 | AB39: BANK | AC39: =+E39-AA39 -> 0
A40: 46108 | B40: IPRA 2026 | C40: LAND TAX | E40: 52850 | T40: =+E40 -> 52850 | AA40: =SUM(F40:Z40) -> 52850 | AB40: BANK | AC40: =+E40-AA40 -> 0
...

Sheet  EXPENSES HOUSE
A1: LANDCO BANK EXPENSES PER HOUSE
C3: SHARED | D3: SALARIES | E3: EXPENSES BY GUESTS | F3: BOAT SKIPPERS CLEANING | G3: BOAT CLEANING MATERIAL | H3: HOUSE KEEPING | I3: HOUSEHOLD EQUIPMENT | J3: PETROL & BATTERY | K3: TOTAL PERSONAL | L3: TOTAL | M3: SHARED EXPENSES | O3: SHARED
B4: CASA LUZ | C4: =+O19 -> 162772.73 | D4: =+' EXPENSES'!V34+' EXPENSES'!V38 -> 0 | H4: =+' EXPENSES'!V45 -> 0 | K4: =SUM(D4:J4) -> 0 | L4: =+C4+K4 -> 162772.73 | M4: SALARIES & WAGES | N4: 320301.15 | O4: =+N4/4 -> 80075.288
B5: CASA AURORA | C5: =+C4 -> 162772.73 | D5: =+' EXPENSES'!W34+' EXPENSES'!W38 -> 0 | F5: 800 | G5: =+' EXPENSES'!W60 -> 0 | I5: =+' EXPENSES'!#REF! -> #REF! | K5: =SUM(D5:J5) -> #REF! | L5: =+C5+K5 -> #REF! | M5: CASUAL WORKERS AND FOOD ALLOWANCE | N5: 21000 | O5: =+N5/4 -> 5250
B6: CASA CAJU | C6: =+C5 -> 162772.73 | D6: =+' EXPENSES'!X34+' EXPENSES'!X38 -> 0 | F6: 1600 | G6: =+' EXPENSES'!X60 -> 0 | H6: =+' EXPENSES'!X48 -> 0 | J6: =+' EXPENSES'!X43+' EXPENSES'!#REF! -> #REF! | K6: =SUM(D6:J6) -> #REF! | L6: =+C6+K6 -> #REF! | M6: OFFICE AND BANK CHARGES | N6: 3946 | O6: =+N6/4 -> 986.5
B7: CASA COCO | C7: =+C6 -> 162772.73 | D7: =+' EXPENSES'!Y34+' EXPENSES'!Y38 -> 0 | I7: =+' EXPENSES'!Y42+' EXPENSES'!Y29 -> 10500 | K7: =SUM(D7:J7) -> 10500 | L7: =+C7+K7 -> 173272.73 | M7: ADMIN CHARGES (BDO & ANDRISA ENS ) | N7: 184126.8 | O7: =+N7/4 -> 46031.7
L8: =SUM(L4:L7) -> #REF! | M8: GAS AND ELECTRISITY | N8: 62895.1 | O8: =+N8/4 -> 15723.775
L9: =+' EXPENSES'!E4 -> 1160648 | M9: MAINTENANCE GENERAL | N9: 24273.6 | O9: =+N9/4 -> 6068.4
L10: =+L8-L9 -> #REF! | M10: MAINTENANCE GARDEN & POOL | N10: 2424.6 | O10: =+N10/4 -> 606.15
M11: SMALL TOOLS | N11: 0 | O11: =+N11/4 -> 0
L12: =+L9/63.25/4 -> 4587.5414 | M12: EQUIPMENT PRESSURE PUMP X 2 | N12: 0 | O12: =+N12/4 -> 0
M13: MAINTENANCE VEHICLES | N13: 0 | O13: =+N13/4 -> 0
M14: INSURANCE & LICENSE | N14: 5125.68 | O14: =+N14/4 -> 1281.42
M15: DIESEL AND PETROL | N15: 14263 | O15: =+N15/4 -> 3565.75
M16: HOUSE KEEPING | N16: 12735 | O16: =+N16/4 -> 3183.75
M17: MARINTINE & MUNICIPAL TAXES IPRA &TAE | N17: 0 | O17: =+N17/4 -> 0
M18: COMMUNITY DONATION | N18: 0 | O18: =+N18/4 -> 0
N19: =SUM(N4:N18) -> 651090.93 | O19: =SUM(O4:O18) -> 162772.73
M24: EXPENSES LUZ | N24: =+' EXPENSES'!#REF! -> #REF! | O24: =+N24 -> #REF!
M25: EXPENSES AURORA | N25: =+' EXPENSES'!#REF! -> #REF! | O25: =+N25 -> #REF!
M26: EXPENSES CAJU | N26: =+' EXPENSES'!#REF! -> #REF! | O26: =+N26 -> #REF!
M27: EXPENSES COCO | N27: =+' EXPENSES'!#REF! -> #REF! | O27: =+N27 -> #REF!
N28: =+N19+N24+N25+N26+N27 -> #REF!
N30: =+' EXPENSES'!#REF! -> #REF!
N31: =+N28-N30 -> #REF!

Sheet MONTHLY FOR THE YEAR
A1: LANDCO EXPENSES
B2: MONTH | C2: EXPENSES | D2: 63.25
B4: 46023 | C4: =+' EXPENSES'!#REF! -> #REF! | D4: =+C4/$D$2 -> #REF!
B5: 46055 | D5: =+C5/$D$2 -> 0
B6: 46087 | D6: =+C6/$D$2 -> 0
B7: 46119 | D7: =+C7/$D$2 -> 0
B8: 46151 | D8: =+C8/$D$2 -> 0
B9: 46183 | D9: =+C9/$D$2 -> 0
B10: 46215 | D10: =+C10/$D$2 -> 0
B11: 46247 | D11: =+C11/$D$2 -> 0
B12: 46279 | D12: =+C12/$D$2 -> 0
B13: 46311 | D13: =+C13/$D$2 -> 0
B14: 46343 | D14: =+C14/$D$2 -> 0
B15: 46375 | D15: =+C15/$D$2 -> 0
C16: =SUM(C4:C15) -> #REF! | D16: =SUM(D4:D15) -> #REF!
B18: AVERAGE | C18: =+C16/9 -> #REF! | D18: =+D16/9 -> #REF!
