Workbook
Name Z_689895ED_8DF8_466C_90EE_5C2362D49AE1__wvu_PrintArea: 'Folha de salarios'!$A$4:$AB$42

Sheet Summary
B1: LANDCO LDA
B3: SUMMARY OF MONTHLY INCOME AND EXPENDITURE
B5: AMOUNTS IN METICAIS | F5: MARCO | H5: 2026
E7: EXCHANGE RATES / CAMBIOS:
E8: Mtn / $ | F8: 63.25
E9: Mtn / R | F9: 3.5
E12: AMOUNTS EXCLUDING IVA
C14: INCOME : | H14: INPUT IVA
H15: CREDITORS | I15: =+Creditors!H19 -> 0
C16: TOTAL SALES | F16: =+'Invoices '!E26 -> 0 | H16: BANK CONTROL | I16: =+'BIM Bank Control Mtn'!J67 -> 0
H17: CASH BOOK | I17: =+'Petty cash '!I37 -> 0
H18: PRE-PAID CARD | I18: =+'Pre-paid'!I29 -> 0
C19: EXPENSES : | H19: ORIGINAL INVOICES OUTSTANDING
H20: TOTAL | I20: =SUM(I15:I19) -> 0
C21: LOAN ACCOUNT EXPENSES
C22: CREDITORS | E22: =+Creditors!G19 -> 0
H23: OUTPUT IVA
C24: BANK PAYMENTS - BIM MZN | E24: ='BIM Bank Control Mtn'!L67 -> 0 | H24: =+'Invoices '!F26 -> 0
C25: PRE-PAID CARD | E25: =+'Pre-paid'!J29 -> 0
C26: CASH PAYMENTS | E26: =+'Petty cash '!J37 -> 750
E28: =SUM(E22:E26) -> 750 | F28: =SUM(F15:F23) -> 0 | H28: CALCULATED IVA PAYABLE / REFUNDABLE
E30: PROFIT / LOSS | F30: =F28-E28 -> -750 | H30: OUTPUT IVA | I30: =H24 -> 0
H31: INPUT IVA | I31: =-I20 -> 0
H32: IVA CREDIT B/F (REF BDO) | I32: =SUM(I30:I31) -> 0
H33: IVA CREDIT ORIGINAL IVA INV PRESENTED PREVIOUS MONTHS | I33: =+[1]Summary!$I$34 -> -895798.42
H34: ESTIMATED IVA (Payable or Refundable): | I34: =SUM(I32:I33) -> -895798.42 | J34: est

Sheet Creditors
B1: LANDCO LDA
B3: CREDITORS
B5: AMOUNTS IN METICAIS | H5: MARCO | I5: 2026
G7: EXCHANGE RATES / CAMBIOS:
G8: Mtn / $ | H8: 63.25
G9: Mtn / R | H9: 3.5
A12: No | B12: DATE | C12: INV | D12: SUPPLIER | E12: DESCRIPTION | F12: ALLOCATION | G12: EXCL AMOUNT | H12: IVA @ 16% | I12: INCL AMOUNT
A15: 1
A16: 2 | G16: =I16-H16 -> 0 | H16: =I16/1.17*0.17 -> 0
A17: 3 | G17: =I17-H17 -> 0 | H17: =I17/1.17*0.17 -> 0
A18: 4 | H18: =I18/1.17*0.17 -> 0
F19: TOTAL PURCHASES / TOTAL DESPESAS | G19: =SUM(G15:G18) -> 0 | H19: =SUM(H15:H18) -> 0 | I19: =SUM(I15:I18) -> 0

Sheet Shareholders investment
B1: LANDCO LDA
B3: SHAREHOLDERS CONTRIBUTION
F5: MARCO | G5: 2026
E7: EXCHANGE RATES / CAMBIOS:
E8: Mtn / $ | F8: 63.25
E9: Mtn / R | F9: 3.5
A12: No | B12: DATE | C12: DEBTOR | D12: DESCRIPTION | E12: CREDIT | F12: DEBIT | G12: BALANCE
A15: 1 | B15: 46098 | C15: WARREN COHEN | D15: SHAREHOLDERS CONTRIBUTION | F15: 21000 | G15: =+F15 -> 21000
A16: =+A15+1 -> 2
A17: =+A16+1 -> 3
A18: =+A17+1 -> 4
A19: =+A18+1 -> 5
A20: =+A19+1 -> 6
A21: =+A20+1 -> 7
A22: =+A21+1 -> 8
A23: =+A22+1 -> 9
G25: =+G15 -> 21000

Sheet Invoices 
B1: LANDCO LDA
B3: SUMMARY OF MONTHLY SALES / SUMMARIO DAS VENDAS MENSAIS
B5: AMOUNTS IN METICAIS | F5: ABRIL | G5: 2026
E7: EXCHANGE RATES / CAMBIOS:
E8: Mtn / $ | F8: 63.25
A12: No | B12: DATE | C12: INV | E12: AMOUNT VALOR | F12: IVA AT | G12: FACTURA
B13: DATA | C13: FAC | D13: DESCRIPTION / DESCRICAO | E13: EXCL IVA | F13: 0.16 | G13: TOTAL
C14: No | G14: INCL IVA
A15: 1 | B15: 46113 | C15: 97 | E15: =+G15/116*100 -> 0 | F15: =+E15*0.16 -> 0 | G15: 0
A16: 2
A17: 3
A18: 4
A19: 5
A20: 6
A21: 7
A22: 8
A23: 9
A24: 10
G25: =IF(C25="","",SUM(E25:F25))
D26: TOTAL SALES / TOTAL VENDAS | E26: =SUM(E15:E25) -> 0 | F26: =SUM(F15:F25) -> 0 | G26: =SUM(G15:G25) -> 0

Sheet BIM Bank Control USD
D1: LANDCO LDA
A2: BANK CONTROL USD
G3: Balance bf | H3: 3591.97
G4: Entrada | H4: =+G42-G13 -> 21000
G5: Soma | H5: =H3+H4 -> 24591.97
A6: Controlo de Bancos | G6: Saída | H6: =+H42 -> 15009.27
A7: Conta nº 93880869 | G7: Existência | H7: =H5-H6 -> 9582.7
A8: NIB 000 100 000 009 388 086 957
E9: BIM - Vilanculos | G9: Valores em USD
A11: Nº | B11: Data | C11: Nº. Cheque | D11: Empresa | E11: Descrição | F11: Allocação | G11: Entradas | H11: Saídas | I11: Saldo | J11: IVA | K11: Nett expense
A12: Doc | C12: / Documento
A13: 1 | B13: 46082 | C13: B/F | D13: BIM | E13: BALANCE FORWARD | G13: =+H3 -> 3591.97 | I13: =+I12+G13-H13 -> 3591.97 | J13: =H13/1.17*0.17 -> 0 | K13: =H13-J13 -> 0
A14: 2 | B14: 46098 | C14: TRF | D14: BIM | E14: TRANSFER FEE | F14: BANK CHARGES | H14: 9.27 | I14: =I13+G14-H14 -> 3582.7 | J14: 0 | K14: =H14-J14 -> 9.27
A15: 3 | B15: 46098 | C15: TRF | D15: WARREN COHEN | E15: SHAREHOLDERS CORTRIBUTION | F15: SHARHOLDERS CONTRIBUTION | G15: 21000 | I15: =I14+G15-H15 -> 24582.7 | J15: 0 | K15: =H15-J15 -> 0
A16: 4 | B16: 46105 | C16: TRF | D16: BIM | E16: TRANSFER DOLLARS TO METICAIS | F16: SUSPENSE | H16: 5000 | I16: =I15+G16-H16 -> 19582.7 | J16: 0 | K16: =H16-J16 -> 5000
A17: 6 | B17: 46108 | C17: TRF | D17: BIM | E17: TRANSFER DOLLARS TO METICAIS | F17: SUSPENSE | H17: 5000 | I17: =I16+G17-H17 -> 14582.7 | J17: 0 | K17: =H17-J17 -> 5000
A18: 5 | B18: 46111 | C18: TRF | D18: BIM | E18: TRANSFER DOLLARS TO METICAIS | F18: SUSPENSE | H18: 5000 | I18: =I17+G18-H18 -> 9582.7 | J18: 0 | K18: =H18-J18 -> 5000
A19: 7 | I19: =I18+G19-H19 -> 9582.7 | J19: 0 | K19: =H19-J19 -> 0
A20: 8 | I20: =I19+G20-H20 -> 9582.7 | J20: =H20/1.17*0.17 -> 0 | K20: =H20-J20 -> 0
A21: 9 | I21: =I20+G21-H21 -> 9582.7 | J21: 0 | K21: =H21-J21 -> 0
A22: 10 | I22: =I21+G22-H22 -> 9582.7 | J22: =H22/1.17*0.17 -> 0 | K22: =H22-J22 -> 0
A23: 11 | I23: =I22+G23-H23 -> 9582.7 | J23: =H23/1.17*0.17 -> 0 | K23: =H23-J23 -> 0
A24: 12 | I24: =I23+G24-H24 -> 9582.7 | J24: =H24/1.17*0.17 -> 0 | K24: =H24-J24 -> 0
A25: 13 | I25: =I24+G25-H25 -> 9582.7 | J25: =H25/1.17*0.17 -> 0 | K25: =H25-J25 -> 0
A26: 14 | I26: =I25+G26-H26 -> 9582.7 | J26: =H26/1.17*0.17 -> 0 | K26: =H26-J26 -> 0
A27: 15 | I27: =I26+G27-H27 -> 9582.7 | J27: =H27/1.17*0.17 -> 0 | K27: =H27-J27 -> 0
A28: 16 | I28: =I27+G28-H28 -> 9582.7 | J28: =H28/1.17*0.17 -> 0 | K28: =H28-J28 -> 0
A29: 17 | I29: =I28+G29-H29 -> 9582.7 | J29: =H29/1.17*0.17 -> 0 | K29: =H29-J29 -> 0
A30: 18 | I30: =I29+G30-H30 -> 9582.7 | J30: =H30/1.17*0.17 -> 0 | K30: =H30-J30 -> 0
A31: 19 | I31: =I30+G31-H31 -> 9582.7 | J31: =H31/1.17*0.17 -> 0 | K31: =H31-J31 -> 0
A32: 20 | I32: =I31+G32-H32 -> 9582.7 | J32: =H32/1.17*0.17 -> 0 | K32: =H32-J32 -> 0
A33: 21 | I33: =I32+G33-H33 -> 9582.7 | J33: =H33/1.17*0.17 -> 0 | K33: =H33-J33 -> 0
... A41: 29 | I41: =I40+G41-H41 -> 9582.7 | J41: =H41/1.17*0.17 -> 0 | K41: =H41-J41 -> 0
G42: =SUM(G13:G41) -> 24591.97 | H42: =SUM(H13:H41) -> 15009.27 | I42: =+G42-H42 -> 9582.7 | J42: =SUM(J13:J41) -> 0 | K42: =SUM(K13:K41) -> 15009.27

Sheet BIM Bank Control Mtn
D1: LANDCO LDA
A2: BANK CONTROL MTN | I2: Balance bf | J2: 272491.84
F3: ABRIL | G3: 2026 | I3: Entrada | J3: =+G67-G11 -> 0
A4: Controlo de Bancos | I4: Soma | J4: =J2+J3 -> 272491.84
A5: Conta nº 93881257 | F5: Valores em Mtn | I5: Saída | J5: =+H67 -> 0
A6: NIB 000 100 000 009 388 125 757 | I6: Existência | J6: =J4-J5 -> 272491.84
E7: BIM - Vilanculos
A9: Nº | B9: Data | C9: Nº. Cheque | D9: Empresa | E9: Descrição | F9: Allocação | G9: Entradas | H9: Saídas | I9: Saldo | J9: IVA | K9: Nett Income | L9: Nett expense
A10: Doc | C10: / Documento
A11: 1 | B11: 46113 | E11: BALANCE CARRY FORWARD | G11: =+J2 -> 272491.84 | I11: =+G11 -> 272491.84 | L11: =H11-J11 -> 0
A12: 1 | I12: =+I11+G12-H12 -> 272491.84 | L12: =H12-J12 -> 0
A13: =+A12+1 -> 2 | I13: =+I12+G13-H13 -> 272491.84 | L13: =H13-J13 -> 0
A14: =+A13+1 -> 3 | I14: =+I13+G14-H14 -> 272491.84 | L14: =H14-J14 -> 0
A15: =+A14+1 -> 4 | I15: =+I14+G15-H15 -> 272491.84 | L15: =H15-J15 -> 0
A16: =+A15+1 -> 5 | I16: =+I15+G16-H16 -> 272491.84 | L16: =H16-J16 -> 0
A17: =+A16+1 -> 6 | I17: =+I16+G17-H17 -> 272491.84 | L17: =H17-J17 -> 0
A18: =+A17+1 -> 7 | I18: =+I17+G18-H18 -> 272491.84 | L18: =H18-J18 -> 0
A19: =+A18+1 -> 8 | I19: =+I18+G19-H19 -> 272491.84 | L19: =H19-J19 -> 0
A20: =+A19+1 -> 9 | I20: =+I19+G20-H20 -> 272491.84 | L20: =H20-J20 -> 0
A21: =+A20+1 -> 10 | I21: =+I20+G21-H21 -> 272491.84 | L21: =+H21-J21 -> 0
A22: =+A21+1 -> 11 | I22: =+I21+G22-H22 -> 272491.84 | L22: =+H22-J22 -> 0
A23: =+A22+1 -> 12 | I23: =+I22+G23-H23 -> 272491.84 | L23: =+H23-J23 -> 0
A24: =+A23+1 -> 13 | I24: =+I23+G24-H24 -> 272491.84 | L24: =+H24-J24 -> 0
A25: =+A24+1 -> 14 | I25: =+I24+G25-H25 -> 272491.84 | L25: =H25-J25 -> 0 | M25: =+I25-269923.07 -> 2568.77
A26: =+A25+1 -> 15 | I26: =+I25+G26-H26 -> 272491.84 | L26: =H26-J26 -> 0
A27: =+A26+1 -> 16 | I27: =+I26+G27-H27 -> 272491.84 | L27: =H27-J27 -> 0
A28: =+A27+1 -> 17 | I28: =+I27+G28-H28 -> 272491.84 | L28: =+H28-J28 -> 0
A29: =+A28+1 -> 18 | I29: =+I28+G29-H29 -> 272491.84 | L29: =H29-J29 -> 0
A30: =+A29+1 -> 19 | I30: =+I29+G30-H30 -> 272491.84 | L30: =H30-J30 -> 0
A31: =+A30+1 -> 20 | I31: =+I30+G31-H31 -> 272491.84 | L31: =H31-J31 -> 0
A32: =+A31+1 -> 21 | I32: =+I31+G32-H32 -> 272491.84 | L32: =H32-J32 -> 0
A33: =+A32+1 -> 22 | I33: =+I32+G33-H33 -> 272491.84 | L33: =H33-J33 -> 0
A34: =+A33+1 -> 23 | I34: =+I33+G34-H34 -> 272491.84 | L34: =H34-J34 -> 0 | N34: =+I37-198797.71 -> 73694.13
A35: =+A34+1 -> 24 | I35: =+I34+G35-H35 -> 272491.84 | L35: =H35-J35 -> 0
A36: =+A35+1 -> 25 | I36: =+I35+G36-H36 -> 272491.84 | L36: =H36-J36 -> 0
A37: =+A36+1 -> 26 | I37: =+I36+G37-H37 -> 272491.84 | L37: =H37-J37 -> 0
A38: =+A37+1 -> 27 | I38: =+I37+G38-H38 -> 272491.84 | L38: =H38-J38 -> 0
A39: =+A38+1 -> 28 | I39: =+I38+G39-H39 -> 272491.84 | L39: =H39-J39 -> 0
A40: =+A39+1 -> 29 | I40: =+I39+G40-H40 -> 272491.84 | L40: =H40-J40 -> 0
A41: =+A40+1 -> 30 | I41: =+I40+G41-H41 -> 272491.84 | L41: =H41-J41 -> 0
...

Sheet Petty cash 
A1: LANDCO LDA
G2: MTn
F3: R E S U M O
F4: Balance bf | G4: -495
F5: Entrada | G5: =+F37 -> 0
F6: Soma | G6: =G4+G5 -> -495
A7: ABRIL | B7: 2026 | F7: Saída | G7: =G37 -> 750
F8: Existência | G8: =G6-G7 -> -1245
A10: DATA | B10: REF | C10: SUPPLIER | D10: DESCRIPTION | E10: ALLOCATION | F10: ENTRADAS | G10: SAIDAS (incl IVA) | I10: IVA | J10: Nett Expenses
A11: 46113 | C11: BALANCE | H11: =+G4 -> -495
C12: PORTADOR | G12: 750 | H12: =+H11+F12-G12 -> -1245 | J12: =+G12-I12 -> 750
H13: =+H12+F13-G13 -> -1245 | J13: =+G13-I13 -> 0
H14: =+H13+F14-G14 -> -1245 | I14: =+G14*0.137931034482759 -> 0 | J14: =+G14-I14 -> 0
H15: =+H14+F15-G15 -> -1245 | I15: =+G15*0.137931034482759 -> 0 | J15: =+G15-I15 -> 0
H16: =+H15+F16-G16 -> -1245 | I16: =+G16*0.137931034482759 -> 0 | J16: =+G16-I16 -> 0
H17: =+H16+F17-G17 -> -1245 | I17: 0 | J17: =+G17-I17 -> 0
H18: =+H17+F18-G18 -> -1245 | I18: 0 | J18: =+G18-I18 -> 0
H19: =+H18+F19-G19 -> -1245 | I19: 0 | J19: =+G19-I19 -> 0
H20: =+H19+F20-G20 -> -1245 | I20: 0 | J20: =+G20-I20 -> 0
H21: =+H20+F21-G21 -> -1245 | I21: 0 | J21: =+G21-I21 -> 0
H22: =+H21+F22-G22 -> -1245 | I22: 0 | J22: =+G22-I22 -> 0
H23: =+H22+F23-G23 -> -1245 | I23: 0
H24: =+H23+F24-G24 -> -1245 | I24: =G24/1.17*0.17 -> 0 | J24: =+G24-I24 -> 0
H25: =+H24+F25-G25 -> -1245 | I25: =G25/1.17*0.17 -> 0 | J25: =+G25-I25 -> 0
H26: =+H25+F26-G26 -> -1245 | I26: =G26/1.17*0.17 -> 0 | J26: =+G26-I26 -> 0
H27: =+H26+F27-G27 -> -1245 | I27: =G27/1.16*0.16 -> 0 | J27: =+G27-I27 -> 0
H28: =H27+F28-G28 -> -1245 | I28: =G28/1.17*0.17 -> 0 | J28: =+G28-I28 -> 0
H29: =H28+F29-G29 -> -1245 | I29: =G29/1.17*0.17 -> 0 | J29: =+G29-I29 -> 0
H30: =H29+F30-G30 -> -1245 | I30: =G30/1.17*0.17 -> 0 | J30: =+G30-I30 -> 0
H31: =H30+F31-G31 -> -1245 | I31: =G31/1.17*0.17 -> 0 | J31: =+G31-I31 -> 0
H32: =H31+F32-G32 -> -1245 | I32: =G32/1.17*0.17 -> 0 | J32: =+G32-I32 -> 0
H33: =H32+F33-G33 -> -1245 | I33: =G33/1.17*0.17 -> 0 | J33: =+G33-I33 -> 0
H34: =H33+F34-G34 -> -1245 | I34: =G34/1.17*0.17 -> 0 | J34: =+G34-I34 -> 0
H35: =H34+F35-G35 -> -1245 | I35: =G35/1.17*0.17 -> 0 | J35: =+G35-I35 -> 0
H36: =H35+F36-G36 -> -1245 | I36: =G36/1.17*0.17 -> 0 | J36: =+G36-I36 -> 0
F37: =SUM(F12:F36) -> 0 | G37: =SUM(G12:G36) -> 750 | H37: =+H36 -> -1245 | I37: =SUM(I12:I36) -> 0 | J37: =SUM(J11:J36) -> 750

Sheet Pre-paid
A1: LANDCO LDA
G2: MTn
F3: R E S U M O
E4: cc | F4: Balance bf | G4: 32537.27
F5: Entrada | G5: =+F29 -> 0
F6: Soma | G6: =G4+G5 -> 32537.27
A7: JANEIRIO | B7: 2026 | F7: Saída | G7: =G29 -> 0
F8: Existência | G8: =G6-G7 -> 32537.27
A10: DATA | B10: REF | C10: SUPPLIER | D10: DESCRIPTION | E10: ALLOCATION | F10: ENTRADAS | G10: SAIDAS (incl IVA) | I10: IVA | J10: Nett Expenses
A11: 46054 | C11: BALANCE | H11: =+G4 -> 32537.27
H12: =+H11+F12-G12 -> 32537.27 | J12: =+G12-I12 -> 0
H13: =+H12+F13-G13 -> 32537.27 | J13: =+G13-I13 -> 0
H14: =+H13+F14-G14 -> 32537.27
H15: =+H14+F15-G15 -> 32537.27
H16: =+H15+F16-G16 -> 32537.27
H17: =+H16+F17-G17 -> 32537.27
H18: =+H17+F18-G18 -> 32537.27
H19: =+H18+F19-G19 -> 32537.27
H20: =+H19+F20-G20 -> 32537.27
H21: =+H20+F21-G21 -> 32537.27
H22: =+H21+F22-G22 -> 32537.27
H23: =+H22+F23-G23 -> 32537.27
H24: =+H23+F24-G24 -> 32537.27
H25: =+H24+F25-G25 -> 32537.27
H26: =H25+F26-G26 -> 32537.27
H27: =H26+F27-G27 -> 32537.27
H28: =H27+F28-G28 -> 32537.27
F29: =SUM(F12:F28) -> 0 | G29: =SUM(G12:G28) -> 0 | H29: =+H28 -> 32537.27 | I29: =SUM(I12:I28) -> 0 | J29: =SUM(J12:J28) -> 0

Sheet Folha de salarios
A4: FOLHA DE SALARIOS | AH4: PAGINA 1
I5: EMPRESA : | N5: LANDCO LIMITADA | V5: NUIT : | X5: 400122792 | AG5: ANO : | AH5: 2025
I6: ACTIVIDADE : | J6: ACTIVIDADE : | N6: TURISMO | V6: LOCALIDADE : | X6: VILANCULOS | AG6: MES : | AH6: Marco
A8: NO | C8: NOME DO TRABALHADOR | D8: Engagement Date | E8: Data de nascimento | F8: NUIT NO | H8: CATEGORIA | I8: RETRIBUICAO | AA8: DESCONTOS
G9: ID | I9: Salario Base 2024 | J9: 2025 | K9: ALIMENTACAO | L9: Pagamentos Retroativos (Back Payment) | M9: DIAS DE TRABALHO | N9: SALARIO MENSAL | O9: NIGHTSHIFT HOURS | P9: 25% GUARDAS | Q9: HORAS CALCULADO 1.5 | R9: VALOR PARA TRABALHOS EXTRAORDINARIOS (CALCULADOOS 1.5) | S9: HORAS CALCULADO 2 | T9: VALOR PARA TRABALHOS EXTRAORDINARIO (CALCULADO 2) | U9: PREMIOS | V9: GRATIFICACOES | W9: DIAS DE FERIAS | X9: FERIA MONTANTE | Y9: Total de Remuneração Mensal | Z9: Salário adiantado (Advance) | AA9: IRPS (A) | AB9: DIVIDA (A) | AC9: INSS (A) | AD9: SIND (A) | AE9: TOTAL DEDUCTIONS | AF9: SALARIO LIQUIDO | AG9: ARREDONDAMENTO | AH9: RUBRICA
A10: 1 | B10: AM | C10: MARCO BEBE GIMO | D10: 39173 | E10: 24963 | F10: 122956547 | G10: 081302847236J | H10: GERENTE | I10: 74180 | J10: 73000 | K10: 8000 | L10: 0 | M10: 30 | N10: =J10/30*M10+K10+L10 -> 81000 | Q10: 0 | R10: =I10/192*Q10*1.5 -> 0 | T10: =N10/192*S10*2 -> 0 | V10: 0 | W10: 0 | X10: =N10/30*W10 -> 0 | Y10: =N10+P10+R10+T10+U10+V10+X10 -> 81000 | AA10: 10437.5 | AC10: =Y10*3% -> 2430 | AD10: =Y10*0.01 -> 810 | AE10: =+Z10+AA10+AB10+AC10+AD10 -> 13677.5 | AF10: =Y10-AE10 -> 67322.5 | AG10: 304762846 | AH10: =SUM(Y10:Y17) -> 164821 | AI10: =+AH10*1.04 -> 171413.84
A11: =+A10+1 -> 2 | B11: AM | C11: ARMINDO QUETANE HOU | D11: 38504 | E11: 26884 | F11: 136243251 | G11: 081304201809J | H11: GUARDA | I11: 10400 | J11: 11336 | L11: 0 | M11: 30 | N11: =J11/30*M11+K11+L11 -> 11336 | O11: 160 | P11: =+N11/M11/8*O11*0.25 -> 1889.3333 | Q11: 0 | R11: =I11/192*Q11*1.5 -> 0 | T11: =N11/192*S11*2 -> 0 | V11: 0 | W11: 0 | X11: =N11/30*W11 -> 0 | Y11: =N11+P11+R11+T11+U11+V11+X11 -> 13225.333 | AC11: =Y11*3% -> 396.76 | AD11: =Y11*0.01 -> 132.25333 | AE11: =+Z11+AA11+AB11+AC11+AD11 -> 529.01333 | AF11: =Y11-AE11 -> 12696.32 | AG11: 312688813
A12: =+A11+1 -> 3 | B12: AM | C12: CONSTANTINO JOSE PENGA | D12: 38504 | E12: 27626 | F12: 122857018 | G12: 080904203552J | H12: GUARDA | I12: 10400 | J12: 11336 | L12: 0 | M12: 30 | N12: =J12/30*M12+K12+L12 -> 11336 | O12: 160 | P12: =+N12/M12/8*O12*0.25 -> 1889.3333 | Q12: 0 | R12: =I12/192*Q12*1.5 -> 0 | T12: =N12/192*S12*2 -> 0 | V12: 0 | W12: 0 | X12: =N12/30*W12 -> 0 | Y12: =N12+P12+R12+T12+U12+V12+X12 -> 13225.333 | AC12: =Y12*3% -> 396.76 | AD12: =Y12*0.01 -> 132.25333 | AE12: =+Z12+AA12+AB12+AC12+AD12 -> 529.01333 | AF12: =Y12-AE12 -> 12696.32 | AG12: 88904090
A13: =+A12+1 -> 4 | B13: AM | C13: ANSELMO LUCAS HUO | D13: 40299 | E13: 28643 | F13: 122748758 | G13: 081300608787A | H13: GUARDA | I13: 10400 | J13: 11336 | L13: 0 | M13: 30 | N13: =J13/30*M13+K13+L13 -> 11336 | O13: 160 | P13: =+N13/M13/8*O13*0.25 -> 1889.3333 | Q13: 0 | R13: =I13/192*Q13*1.5 -> 0 | T13: =N13/192*S13*2 -> 0 | V13: 0 | W13: 0 | X13: =N13/30*W13 -> 0 | Y13: =N13+P13+R13+T13+U13+V13+X13 -> 13225.333 | AC13: =Y13*3% -> 396.76 | AD13: =Y13*0.01 -> 132.25333 | AE13: =+Z13+AA13+AB13+AC13+AD13 -> 529.01333 | AF13: =Y13-AE13 -> 12696.32 | AG13: 311846368
A14: =+A13+1 -> 5 | B14: AM | C14: CISTORA JOAO TANGUNE | D14: 43709 | E14: 33551 | F14: 162213849 | G14: 100106722368D | H14: EMPREGADA | I14: 10000 | J14: 10900 | L14: 0 | M14: 30 | N14: =J14/30*M14+K14+L14 -> 10900 | P14: =+N14/M14/8*O14*0.25 -> 0 | Q14: 0 | R14: =I14/192*Q14*1.5 -> 0 | T14: =N14/192*S14*2 -> 0 | V14: 0 | W14: 0 | X14: =N14/30*W14 -> 0 | Y14: =N14+P14+R14+T14+U14+V14+X14 -> 10900 | AC14: =Y14*3% -> 327 | AD14: =Y14*0.01 -> 109 | AE14: =+Z14+AA14+AB14+AC14+AD14 -> 436 | AF14: =Y14-AE14 -> 10464 | AG14: 465121888
A15: =+A14+1 -> 6 | B15: AM | C15: EMILIO GELSON ZIBANE | D15: 43709 | E15: 35712 | F15: 162213180 | G15: 081306342811Q | H15: JARDINERO | I15: 10500 | J15: 11445 | L15: 0 | M15: 30 | N15: =J15/30*M15+K15+L15 -> 11445 | P15: =+N15/M15/8*O15*0.25 -> 0 | Q15: 0 | R15: =I15/192*Q15*1.5 -> 0 | T15: =N15/192*S15*2 -> 0 | V15: 0 | W15: 0 | X15: =N15/30*W15 -> 0 | Y15: =N15+P15+R15+T15+U15+V15+X15 -> 11445 | Z15: 2300 | AC15: =Y15*3% -> 343.35 | AD15: =Y15*0.01 -> 114.45 | AE15: =+Z15+AA15+AB15+AC15+AD15 -> 2757.8 | AF15: =Y15-AE15 -> 8687.2 | AG15: 465126932
A16: =+A15+1 -> 7 | B16: AM | C16: ALMEIDA ANTONIO VILANCULO | D16: 44442 | E16: 33513 | F16: 151700586 | G16: 081306518566C | H16: JARDINERO | I16: 10000 | J16: 10900 | L16: 0 | M16: 30 | N16: =J16/30*M16+K16+L16 -> 10900 | P16: =+N16/M16/8*O16*0.25 -> 0 | Q16: 0 | R16: =I16/192*Q16*1.5 -> 0 | T16: =N16/192*S16*2 -> 0 | V16: 0 | W16: 0 | X16: =N16/30*W16 -> 0 | Y16: =N16+P16+R16+T16+U16+V16+X16 -> 10900 | AC16: =Y16*3% -> 327 | AD16: =Y16*0.01 -> 109 | AE16: =+Z16+AA16+AB16+AC16+AD16 -> 436 | AF16: =Y16-AE16 -> 10464 | AG16: 784781120
A17: =+A16+1 -> 8 | B17: AM | C17: FELIX CARLOS MASSUANGANHE | D17: 45809 | E17: 37588 | F17: 145174406 | G17: 089908873322B | H17: JARDINERO | I17: 10000 | J17: 10900 | L17: 0 | M17: 30 | N17: =J17/30*M17+K17+L17 -> 10900 | P17: =+N17/M17/8*O17*0.25 -> 0 | Q17: 0 | R17: =I17/192*Q17*1.5 -> 0 | T17: =N17/192*S17*2 -> 0 | V17: 0 | W17: 0 | X17: =N17/30*W17 -> 0 | Y17: =N17+P17+R17+T17+U17+V17+X17 -> 10900 | AC17: =Y17*3% -> 327 | AD17: =Y17*0.01 -> 109 | AE17: =+Z17+AA17+AB17+AC17+AD17 -> 436 | AF17: =Y17-AE17 -> 10464 | AG17: 1236577535
A18: =+A17+1 -> 9 | B18: H1 | C18: GILDA DALARIO FALACO MUABASA | D18: 39546 | E18: 30536 | F18: 122997979 | G18: 081304201799M | H18: EMPREGADA | I18: 10050 | J18: 10955 | L18: 0 | M18: 30 | N18: =J18/30*M18+K18+L18 -> 10955 | P18: =+N18/M18/8*O18*0.25 -> 0 | Q18: 0 | R18: =I18/192*Q18*1.5 -> 0 | T18: =N18/192*S18*2 -> 0 | V18: 0 | W18: 0 | X18: =N18/30*W18 -> 0 | Y18: =N18+P18+R18+T18+U18+V18+X18 -> 10955 | AC18: =Y18*3% -> 328.65 | AD18: =Y18*0.01 -> 109.55 | AE18: =+Z18+AA18+AB18+AC18+AD18 -> 438.2 | AF18: =Y18-AE18 -> 10516.8 | AG18: 312354163 | AH18: =SUM(Y18:Y20)-6500 -> 34870.875 | AI18: =+AH18*1.04 -> 36265.71
A19: =+A18+1 -> 10 | B19: H1 | C19: SERGIO FENIASSE BUANE | D19: 43221 | E19: 31255 | F19: 158140764 | G19: 081307623643I | H19: COZINHEIRO | I19: 13600 | J19: 14824 | L19: 0 | M19: 30 | N19: =J19/30*M19+K19+L19 -> 14824 | Q19: 0 | R19: =I19/192*Q19*1.5 -> 0 | T19: =N19/192*S19*2 -> 0 | V19: 0 | W19: 0 | X19: =N19/30*W19 -> 0 | Y19: =N19+P19+R19+T19+U19+V19+X19 -> 14824 | AC19: =Y19*3% -> 444.72 | AD19: =Y19*0.01 -> 148.24 | AE19: =+Z19+AA19+AB19+AC19+AD19 -> 592.96 | AF19: =Y19-AE19 -> 14231.04 | AG19: 426758485
A20: =+A19+1 -> 11 | B20: H1/H4 | C20: AMINOSSE ARNALDO TANGUNE | D20: 44829 | E20: 35471 | F20: 155246677 | G20: 081306019850S | H20: CAPITÃO DE BARCO | I20: 13000 | J20: 14170 | L20: 0 | M20: 30 | N20: =J20/30*M20+K20+L20 -> 14170 | Q20: 14 | R20: =I20/192*Q20*1.5 -> 1421.875 | T20: =N20/192*S20*2 -> 0 | V20: 0 | W20: 0 | X20: =N20/30*W20 -> 0 | Y20: =N20+P20+R20+T20+U20+V20+X20 -> 15591.875 | AC20: =Y20*3% -> 467.75625 | AD20: =Y20*0.01 -> 155.91875 | AE20: =+Z20+AA20+AB20+AC20+AD20 -> 623.675 | AF20: =Y20-AE20 -> 14968.2 | AG20: 000800007745713610195
A21: =+A20+1 -> 12 | B21: H2 | C21: SERGIO FRANCISCO TANGUNE ZITO | D21: 38367 | E21: 32345 | F21: 123147911 | G21: 081304202030F | H21: GHILLIE | I21: 13650 | J21: 14879 | L21: 0 | M21: 30 | N21: =J21/30*M21+K21+L21 -> 14879 | Q21: 0 | R21: =I21/192*Q21*1.5 -> 0 | T21: =N21/192*S21*2 -> 0 | V21: 0 | W21: 0 | X21: =N21/30*W21 -> 0 | Y21: =N21+P21+R21+T21+U21+V21+X21 -> 14879 | AA21: 129.49 | AC21: =Y21*3% -> 446.37 | AD21: =Y21*0.01 -> 148.79 | AE21: =+Z21+AA21+AB21+AC21+AD21 -> 724.65 | AF21: =Y21-AE21 -> 14154.35 | AG21: 311712702 | AH21: =SUM(Y21:Y24) -> 58534 | AI21: =+AH21*1.04 -> 60875.36
A22: =+A21+1 -> 13 | B22: H2 | C22: VITORIA FRANCISCO ZIBANE | D22: 44809 | E22: 27185 | F22: 100807841 | G22: 080101896345N | H22: EMPREGADA | I22: 10050 | J22: 10955 | L22: 0 | M22: 30 | N22: =J22/30*M22+K22+L22 -> 10955 | Q22: 0 | R22: =I22/192*Q22*1.5 -> 0 | T22: =N22/192*S22*2 -> 0 | V22: 0 | W22: 0 | X22: =N22/30*W22 -> 0 | Y22: =N22+P22+R22+T22+U22+V22+X22 -> 10955 | AC22: =Y22*3% -> 328.65 | AD22: =Y22*0.01 -> 109.55 | AE22: =+Z22+AA22+AB22+AC22+AD22 -> 438.2 | AF22: =Y22-AE22 -> 10516.8 | AG22: 98059241
A23: =+A22+1 -> 14 | B23: H2 | C23: INACIO FABIAO TIMBE | D23: 43116 | E23: 31134 | F23: 120921363 | G23: 081301192306B | H23: CAPITÃO DE BARCO | I23: 15000 | J23: 16350 | L23: 0 | M23: 30 | N23: =J23/30*M23+K23+L23 -> 16350 | Q23: 0 | R23: =I23/192*Q23*1.5 -> 0 | T23: =N23/192*S23*2 -> 0 | V23: 0 | W23: 0 | X23: =N23/30*W23 -> 0 | Y23: =N23+P23+R23+T23+U23+V23+X23 -> 16350 | AC23: =Y23*3% -> 490.5 | AD23: =Y23*0.01 -> 163.5 | AE23: =+Z23+AA23+AB23+AC23+AD23 -> 654 | AF23: =Y23-AE23 -> 15696 | AG23: 411440730
A24: =+A23+1 -> 15 | B24: H2 | C24: CALDERONE AGOSTINHO CHIVALE | D24: 45139 | E24: 32973 | F24: 147597851 | G24: 080901102777C | H24: COZINHEIRO | I24: 15000 | J24: 16350 | L24: 0 | M24: 30 | N24: =J24/30*M24+K24+L24 -> 16350 | Q24: 0 | R24: =I24/192*Q24*1.5 -> 0 | T24: =N24/192*S24*2 -> 0 | V24: 0 | W24: 0 | X24: =N24/30*W24 -> 0 | Y24: =N24+P24+R24+T24+U24+V24+X24 -> 16350 | Z24: 1500 | AC24: =Y24*3% -> 490.5 | AD24: =Y24*0.01 -> 163.5 | AE24: =+Z24+AA24+AB24+AC24+AD24 -> 2154 | AF24: =Y24-AE24 -> 14196 | AG24: '000800004412814610113
A25: =+A24+1 -> 16 | B25: H3 | C25: PEDRO SEBASTIAO NHAMIRE | D25: 44409 | E25: 33067 | F25: 121952742 | G25: 081304002553M | H25: JARDINERO/GHILLIE | I25: 10500 | J25: 11445 | L25: 0 | M25: 30 | N25: =J25/30*M25+K25+L25 -> 11445 | Q25: 0 | R25: =I25/192*Q25*1.5 -> 0 | T25: =N25/192*S25*2 -> 0 | V25: 0 | W25: 0 | X25: =N25/30*W25 -> 0 | Y25: =N25+P25+R25+T25+U25+V25+X25 -> 11445 | AC25: =Y25*3% -> 343.35 | AD25: =Y25*0.01 -> 114.45 | AE25: =+Z25+AA25+AB25+AC25+AD25 -> 457.8 | AF25: =Y25-AE25 -> 10987.2 | AG25: 393221511 | AH25: =SUM(Y25:Y27) -> 36625 | AI25: =+AH25*1.04 -> 38090
A26: =+A25+1 -> 17 | B26: H3 | C26: ROCINA CAHIWANE TIMBE | D26: 38418 | E26: 31414 | F26: 136714831 | G26: 081304202071I | H26: EMPREGADA | I26: 10050 | J26: 10955 | L26: 0 | M26: 30 | N26: =J26/30*M26+K26+L26 -> 10955 | Q26: 0 | R26: =I26/192*Q26*1.5 -> 0 | T26: =N26/192*S26*2 -> 0 | V26: 0 | W26: 0 | X26: =N26/30*W26 -> 0 | Y26: =N26+P26+R26+T26+U26+V26+X26 -> 10955 | AC26: =Y26*3% -> 328.65 | AD26: =Y26*0.01 -> 109.55 | AE26: =+Z26+AA26+AB26+AC26+AD26 -> 438.2 | AF26: =Y26-AE26 -> 10516.8 | AG26: 313333863
A27: =+A26+1 -> 18 | B27: H3 | C27: ALEXANDRE LUCAS MASSUANGANHE | D27: 41275 | E27: 31417 | F27: 125028217 | G27: 080101890971M | H27: COZINHEIRO | I27: 13050 | J27: 14225 | L27: 0 | M27: 30 | N27: =J27/30*M27+K27+L27 -> 14225 | Q27: 0 | R27: =I27/192*Q27*1.5 -> 0 | T27: =N27/192*S27*2 -> 0 | V27: 0 | W27: 0 | X27: =N27/30*W27 -> 0 | Y27: =N27+P27+R27+T27+U27+V27+X27 -> 14225 | AC27: =Y27*3% -> 426.75 | AD27: =Y27*0.01 -> 142.25 | AE27: =+Z27+AA27+AB27+AC27+AD27 -> 569 | AF27: =Y27-AE27 -> 13656 | AG27: 305745068
A28: =+A27+1 -> 19 | B28: H4 | C28: JELSON QUALDADE ZIVANE | D28: 38473 | E28: 28017 | F28: 123151488 | G28: 081304202020M | H28: JARDINERO/COZINHA | I28: 10500 | J28: 11445 | L28: 0 | M28: 30 | N28: =J28/30*M28+K28+L28 -> 11445 | Q28: 0 | R28: =I28/192*Q28*1.5 -> 0 | T28: =N28/192*S28*2 -> 0 | V28: 0 | W28: 0 | X28: =N28/30*W28 -> 0 | Y28: =N28+P28+R28+T28+U28+V28+X28 -> 11445 | Z28: 5000 | AC28: =Y28*3% -> 343.35 | AD28: =Y28*0.01 -> 114.45 | AE28: =+Z28+AA28+AB28+AC28+AD28 -> 5457.8 | AF28: =Y28-AE28 -> 5987.2 | AG28: 311818141 | AH28: =SUM(Y28:Y30)+6500 -> 43125 | AI28: =+AH28*1.04 -> 44850
A29: =+A28+1 -> 20 | B29: H4 | C29: MONIS TSANZIUANE CHIVALE | D29: 44593 | E29: 27010 | F29: 108267186 | G29: 081304122145F | H29: COZINHEIRO | I29: 13050 | J29: 14225 | L29: 0 | M29: 30 | N29: =J29/30*M29+K29+L29 -> 14225 | Q29: 0 | R29: =I29/192*Q29*1.5 -> 0 | T29: =N29/192*S29*2 -> 0 | V29: 0 | W29: 0 | X29: =N29/30*W29 -> 0 | Y29: =N29+P29+R29+T29+U29+V29+X29 -> 14225 | AC29: =Y29*3% -> 426.75 | AD29: =Y29*0.01 -> 142.25 | AE29: =+Z29+AA29+AB29+AC29+AD29 -> 569 | AF29: =Y29-AE29 -> 13656 | AG29: 169475394
A30: =+A29+1 -> 21 | B30: H4 | C30: EVELIN NELSON BERNARDO | D30: 44809 | E30: 31326 | F30: 122598829 | G30: 050201822463P | H30: EMPREGADA | I30: 10050 | J30: 10955 | L30: 0 | M30: 30 | N30: =J30/30*M30+K30+L30 -> 10955 | Q30: 0 | R30: =I30/192*Q30*1.5 -> 0 | T30: =N30/192*S30*2 -> 0 | V30: 0 | W30: 0 | X30: =N30/30*W30 -> 0 | Y30: =N30+P30+R30+T30+U30+V30+X30 -> 10955 | AC30: =Y30*3% -> 328.65 | AD30: =Y30*0.01 -> 109.55 | AE30: =+Z30+AA30+AB30+AC30+AD30 -> 438.2 | AF30: =Y30-AE30 -> 10516.8 | AG30: 257804370
J31: =SUM(J10:J30) -> 322886 | L31: =SUM(L10:L30) -> 0 | N31: =SUM(N10:N30) -> 330886 | P31: =SUM(P10:P30) -> 5668 | Q31: =SUM(Q10:Q30) -> 14 | R31: =SUM(R10:R30) -> 1421.875 | S31: =SUM(S10:S30) -> 0 | T31: =SUM(T10:T30) -> 0 | U31: =SUM(U10:U30) -> 0 | V31: =SUM(V10:V30) -> 0 | W31: =SUM(W10:W30) -> 0 | ... AF31: =SUM(AF10:AF30) -> 305089.85 | AH31: =SUM(AH10:AH30) -> 337975.88
AA32: 7% INSS | AC32: =+Y31*0.07 -> 23658.311 | AG32: 4% INSS | AH32: =+AH31*0.04 -> 13519.035
AF34: =SUM(AF31:AF33) -> 305089.85 | AH34: =SUM(AH31:AH32) -> 351494.91 | AI34: =SUM(AI10:AI33) -> 351494.91
R36: DECLARACAO
A37: ( A ) | C37: Riscar o que nao interessa. | N37: Declaro que nesta data, efectuei o pagamento dos salarios constantes desta
A38: ( B ) | C38: Assinalar com M os trabalhadores de menor idade | N38: folha, aos trabalhadores nela mencionados, na presenca de duas testemunhas
A39: ( C ) | C39: Nao preencher quando se trata de trabalhadores ao dia. | N39: que comigo, pagador, vao assinar.
A40: ( D ) | C40: Descontos permitidos por lei
N41: Data :

Sheet Original Inv Outstanding
B1: LANDCO LDA
B3: Original Iva Invoices Outstanding From This Month
B5: AMOUNTS IN METICAIS | F5: JANEIRIO | G5: 2026
E7: EXCHANGE RATES / CAMBIOS:
E8: Mtn / $ | F8: 63.25
E9: Mtn / R | F9: 3.5
A12: No | B12: DATE | C12: INV | E12: AMOUNT VALOR | F12: IVA AT | G12: AMOUNT
B13: DATA | C13: NR | D13: DESCRIPTION / DESCRICAO | E13: EXCL IVA | F13: 0.16
A15: 1
A16: 2 | F16: =G16/1.16*0.16 -> 0
A17: 3 | F17: =G17/1.16*0.16 -> 0
A18: 4 | F18: =G18/1.16*0.16 -> 0
A19: 5 | F19: =G19/1.16*0.16 -> 0
A20: 6
A21: 7
A22: 8
A23: 9
A24: 10
E25: =SUM(E15:E24) -> 0 | F25: =SUM(F15:F24) -> 0 | G25: =SUM(G15:G24) -> 0
B29: LANDCO LDA
B31: Original Iva Invoices Outstanding From Previous Month Submitted This Month
B33: AMOUNTS IN METICAIS | F33: AUG | G33: 2024
E35: EXCHANGE RATES / CAMBIOS:
E36: Mtn / $ | F36: 63.25
E37: Mtn / R | F37: =F9 -> 3.5
A40: No | B40: DATE | C40: INV | E40: AMOUNT VALOR | F40: IVA AT | G40: AMOUNT
B41: DATA | C41: NR | D41: DESCRIPTION / DESCRICAO | E41: EXCL IVA | F41: 0.17
A43: 1 | E43: =G43-F43 -> 0 | F43: 0
A44: 2 | E44: =G44-F44 -> 0 | F44: 0
A45: 3 | E45: =G45-F45 -> 0 | F45: =G45/1.17*0.17 -> 0
A46: 4 | E46: =G46-F46 -> 0 | F46: =G46/1.17*0.17 -> 0
A47: 5 | E47: =G47-F47 -> 0 | F47: =G47/1.17*0.17 -> 0
A48: 6 | E48: =G48-F48 -> 0 | F48: =G48/1.17*0.17 -> 0
A49: 7 | E49: =G49-F49 -> 0 | F49: =G49/1.17*0.17 -> 0
A50: 8 | E50: =G50-F50 -> 0 | F50: =G50/1.17*0.17 -> 0
A51: 9 | E51: =G51-F51 -> 0 | F51: =G51/1.17*0.17 -> 0
A52: 10 | E52: =G52-F52 -> 0 | F52: =G52/1.17*0.17 -> 0
E53: =SUM(E43:E52) -> 0 | F53: =SUM(F43:F52) -> 0 | G53: =SUM(G43:G52) -> 0
